Workbook

Sheet Capa
C1: =SUM(H2-H4) -> 0
C2: Desconto | H2: 0
C4: Acréscimo | H4: 0
C6: Digite acima um desconto ou acréscimo para aplicar em todos valores da tabela. O desconto será subtraido do acréscimo se os dois forem digitados.
A23: *Pedidos por telefone (RESPONSABILIDADE SERÁ DO CLIENTE)
A25: *Confira os tecidos adquiridos antes de cortar, pois não serão aceitas reclamações caso o tecido esteja cortado ou confeccionado.
A28: *Atenção: Tabela com preço especial somente para revendedores
A30: * Os Tecidos Amassados podem sofrer alterações na largura e na textura
A32: * Os Tecidos que possuem algodão e linho em sua composição poderão sofrer encolhimento se não lavados a seco
A35: * Os tecidos podem sofrer diferença de tonalidade de uma remessa para outra
A37: *Não trocamos tecidos e varões cortados
A40: SETEMBRO - 2024

Sheet Promocionais-Book 06
A1: TECIDOS PROMOCIONAIS - SOB CONSULTA
A2: CODIGO | B2: DESCRIÇÃO | D2: LARGURA | E2: CORTE | F2: PEÇA | H2: CORTE | I2: PEÇA
A3: 1030 | B3: VOIL LISO NACIONAL (SOMENTE CORES 11-12-16-17-18-21-33-38) | D3: 3 | E3: =SUM(H3-(H3*Capa!$C$1)) -> 7.67 | F3: =SUM(I3-(I3*Capa!$C$1)) -> 7.29 | H3: 7.67 | I3: 7.29
A4: 1031 | B4: VOIL AMASSADO CORTTEX (01-02-04-05-09-10-26-28-40 FORA DE LINHA) | D4: 2,65/2,70 | E4: =SUM(H4-(H4*Capa!$C$1)) -> 8.89 | F4: =SUM(I4-(I4*Capa!$C$1)) -> 8.27 | H4: 8.89 | I4: 8.27
A5: 1037 | B5: MALHA JERSEY BRASS (PROMOCIONAL NAS CORES: 07-10-11-22) | D5: 1.55 | E5: =SUM(H5-(H5*Capa!$C$1)) -> 7.28 | F5: =SUM(I5-(I5*Capa!$C$1)) -> 6.77 | H5: 7.28 | I5: 6.77
A6: 1037 | B6: MALHA JERSEY BRASS (CORES: 01-05-06-08-09-15-16-19-21-25-27-31-32-35) | D6: 1.55 | E6: =SUM(H6-(H6*Capa!$C$1)) -> 11.6 | F6: =SUM(I6-(I6*Capa!$C$1)) -> 10.78 | H6: 11.6 | I6: 10.78
A7: 1048 | B7: FORRO PESADO TRAMAXUS (SOB CONSULTA) | D7: 3 | E7: =SUM(H7-(H7*Capa!$C$1)) -> 10.73 | F7: =SUM(I7-(I7*Capa!$C$1)) -> 10.2 | H7: 10.73 | I7: 10.2
A8: 4017 | B8: VOIL LOS ANGELES | D8: 3 | E8: =SUM(H8-(H8*Capa!$C$1)) -> 20.92 | F8: =SUM(I8-(I8*Capa!$C$1)) -> 19.45 | H8: 20.92 | I8: 19.45
A9: 5006 | B9: VOIL NAGOIA (SOMENTE COR 03) | D9: 2.9 | E9: =SUM(H9-(H9*Capa!$C$1)) -> 38.6 | F9: =SUM(I9-(I9*Capa!$C$1)) -> 36.67 | H9: 38.6 | I9: 36.67
A10: 5007 | B10: VOIL SENDAI (SOMENTE COR 01 E COR 03) | D10: 2.9 | E10: =SUM(H10-(H10*Capa!$C$1)) -> 40.98 | F10: =SUM(I10-(I10*Capa!$C$1)) -> 38.93 | H10: 40.98 | I10: 38.93
A11: 7003 | B11: LINHO PANAMA | D11: 3 | E11: =SUM(H11-(H11*Capa!$C$1)) -> 59.54 | F11: =SUM(I11-(I11*Capa!$C$1)) -> 56.57 | H11: 59.54 | I11: 56.57
A12: 7021 | B12: VOIL SEVILHA | D12: 3 | E12: =SUM(H12-(H12*Capa!$C$1)) -> 32.34 | F12: =SUM(I12-(I12*Capa!$C$1)) -> 30.72 | H12: 32.34 | I12: 30.72
A13: 7033 | B13: VOIL MATISSE (SOMENTE COR 05) | D13: 2.9 | E13: =SUM(H13-(H13*Capa!$C$1)) -> 18.76 | F13: =SUM(I13-(I13*Capa!$C$1)) -> 17.83 | H13: 18.76 | I13: 17.83
A14: 7034 | B14: *TAFETÁ FLAMÊ LISO (SOMENTE COR 07) | D14: 2.8 | E14: =SUM(H14-(H14*Capa!$C$1)) -> 12.99 | F14: =SUM(I14-(I14*Capa!$C$1)) -> 12.34 | H14: 12.99 | I14: 12.34
A15: 7035 | B15: *TAFETÁ FLAMÊ LIST (SOMENTE COR 03) | D15: 2.8 | E15: =SUM(H15-(H15*Capa!$C$1)) -> 12.99 | F15: =SUM(I15-(I15*Capa!$C$1)) -> 12.34 | H15: 12.99 | I15: 12.34
A16: 7041 | B16: LINHO BRISTOL II | D16: 3 | E16: =SUM(H16-(H16*Capa!$C$1)) -> 24.43 | F16: =SUM(I16-(I16*Capa!$C$1)) -> 23.21 | H16: 24.43 | I16: 23.21
... A18: 7053 | B18: VOIL DENVER AMASSADO (SOMENTE COR 01) | D18: 2.6 | E18: =SUM(H18-(H18*Capa!$C$1)) -> 23.46 | F18: =SUM(I18-(I18*Capa!$C$1)) -> 22.29 | H18: 23.46 | I18: 22.29
A19: BOOK 06 - PREMIUM COLLECTION
A20: CODIGO | B20: LARGURA | C20: CORTE | E20: PEÇA | H20: CORTE | I20: PEÇA
A21: 6001-01 | B21: 1.4 | C21: =SUM(H21-(H21*Capa!$C$1)) -> 44.65 | E21: =SUM(I21-(I21*Capa!$C$1)) -> 42.41 | H21: 44.65 | I21: 42.41
A22: 6006 | B22: 1.4 | C22: =SUM(H22-(H22*Capa!$C$1)) -> 47.68 | E22: =SUM(I22-(I22*Capa!$C$1)) -> 45.29 | H22: 47.68 | I22: 45.29
A23: 6012 | B23: 1.4 | C23: =SUM(H23-(H23*Capa!$C$1)) -> 45.29 | E23: =SUM(I23-(I23*Capa!$C$1)) -> 43.02 | H23: 45.29 | I23: 43.02
A24: 6015 | B24: 1.4 | C24: =SUM(H24-(H24*Capa!$C$1)) -> 50.93 | E24: =SUM(I24-(I24*Capa!$C$1)) -> 48.39 | H24: 50.93 | I24: 48.39
A25: 6016 | B25: 1.4 | C25: =SUM(H25-(H25*Capa!$C$1)) -> 38.48 | E25: =SUM(I25-(I25*Capa!$C$1)) -> 40.4 | H25: 38.48 | I25: 40.4
A26: 6018 | B26: 1.4 | C26: =SUM(H26-(H26*Capa!$C$1)) -> 47.84 | E26: =SUM(I26-(I26*Capa!$C$1)) -> 45.44 | H26: 47.84 | I26: 45.44
A27: 6019-02 | B27: 1.4 | C27: =SUM(H27-(H27*Capa!$C$1)) -> 39.23 | E27: =SUM(I27-(I27*Capa!$C$1)) -> 37.26 | H27: 39.23 | I27: 37.26
A28: 6020-02 | B28: 1.4 | C28: =SUM(H28-(H28*Capa!$C$1)) -> 40.87 | E28: =SUM(I28-(I28*Capa!$C$1)) -> 38.82 | H28: 40.87 | I28: 38.82
A29: 6023-01 | B29: 1.4 | C29: =SUM(H29-(H29*Capa!$C$1)) -> 41.05 | E29: =SUM(I29-(I29*Capa!$C$1)) -> 39 | H29: 41.05 | I29: 39
A30: 6024 | B30: 1.4 | C30: =SUM(H30-(H30*Capa!$C$1)) -> 41.05 | E30: =SUM(I30-(I30*Capa!$C$1)) -> 39 | H30: 41.05 | I30: 39
A31: 6025 | B31: 1.4 | C31: =SUM(H31-(H31*Capa!$C$1)) -> 41.05 | E31: =SUM(I31-(I31*Capa!$C$1)) -> 39 | H31: 41.05 | I31: 39
A32: 6026 | B32: 1.4 | C32: =SUM(H32-(H32*Capa!$C$1)) -> 42.84 | E32: =SUM(I32-(I32*Capa!$C$1)) -> 40.69 | H32: 42.84 | I32: 40.69
A33: BOOK 09 - BASIC
A34: CODIGO | B34: DESCRIÇÃO | E34: LARGURA | F34: CORTE | H34: CORTE
A35: 9001 | B35: RUSTICO PESADO | E35: 2.9 | F35: =SUM(H35-(H35*Capa!$C$1)) -> 9.46 | H35: 9.46
A36: 9003 | B36: GORGURINHO (CORES 04-05-09-10-11-16) | E36: 2.8 | F36: =SUM(H36-(H36*Capa!$C$1)) -> 12.21 | H36: 12.21
A37: 9004 | B37: VOIL LISO (SOB CONSULTA NAS CORES: 10-11-15-16-17-20-32-34) | E37: 3 | F37: =SUM(H37-(H37*Capa!$C$1)) -> 7.67 | H37: 7.67
A38: 9006 | B38: VELUDO | E38: 1.46 | F38: =SUM(H38-(H38*Capa!$C$1)) -> 16.75 | H38: 16.75
A39: 9007 | B39: OXFORD (CORES 03-04-07-08-10) | E39: 2.8 | F39: =SUM(H39-(H39*Capa!$C$1)) -> 6.78 | H39: 6.78
A40: 9008 | B40: SARJA (CORES 04-05-09-10-11-12-13-16) | E40: 2.8 | F40: =SUM(H40-(H40*Capa!$C$1)) -> 11.31 | H40: 11.31
A41: 9009 | B41: CETIM LISO (CORES 03-05-06-08-09-10-12-13-14) | E41: 3 | F41: =SUM(H41-(H41*Capa!$C$1)) -> 8.33 | H41: 8.33
...

Sheet Book 10
A1: BOOK 10
A2: CODIGO | B2: DESCRIÇÃO | D2: LARGURA | E2: CORTE | F2: PEÇA | H2: CORTE | I2: PEÇA
A3: *10001 | B3: TRICÔ HERA (PROMOCIONAL) | D3: 1.4 | E3: =SUM(H3-(H3*Capa!$C$1)) -> 83.65 | F3: =SUM(I3-(I3*Capa!$C$1)) -> 79.47 | H3: 83.65 | I3: 79.47
A4: 10003 | B4: TRICÔ PERSEU | D4: 1.45 | E4: =SUM(H4-(H4*Capa!$C$1)) -> 78.9 | F4: =SUM(I4-(I4*Capa!$C$1)) -> 75.14 | H4: 78.9 | I4: 75.14
A5: 10004 | B5: TRICÔ CRATOS | D5: 1.45 | E5: =SUM(H5-(H5*Capa!$C$1)) -> 92.56 | F5: =SUM(I5-(I5*Capa!$C$1)) -> 97.18 | H5: 92.56 | I5: 97.18
A6: *10005 | B6: LINHO ELITE (PROMOCIONAL) | D6: 2.8 | E6: =SUM(H6-(H6*Capa!$C$1)) -> 95.95 | F6: =SUM(I6-(I6*Capa!$C$1)) -> 91.15 | H6: 95.95 | I6: 91.15
A7: 10006 | B7: LINHO ALFEU | D7: 2.9 | E7: =SUM(H7-(H7*Capa!$C$1)) -> 90.98 | F7: =SUM(I7-(I7*Capa!$C$1)) -> 86.46 | H7: 90.98 | I7: 86.46
A8: 10007 | B8: LINHO URÂNIA | D8: 2.9 | E8: =SUM(H8-(H8*Capa!$C$1)) -> 97.2 | F8: =SUM(I8-(I8*Capa!$C$1)) -> 92.57 | H8: 97.2 | I8: 92.57
A9: 10008 | B9: LINHO RAMI | D9: 3 | E9: =SUM(H9-(H9*Capa!$C$1)) -> 54.92 | F9: =SUM(I9-(I9*Capa!$C$1)) -> 52.17 | H9: 54.92 | I9: 52.17
A10: *10009 | B10: LINHO PAPIRO (PROMOCIONAL) | D10: 2.95 | E10: =SUM(H10-(H10*Capa!$C$1)) -> 29.33 | F10: =SUM(I10-(I10*Capa!$C$1)) -> 27.86 | H10: 29.33 | I10: 27.86
A11: *10010 | B11: LINHO NOBRE (PROMOCIONAL) | D11: 3 | E11: =SUM(H11-(H11*Capa!$C$1)) -> 42.13 | F11: =SUM(I11-(I11*Capa!$C$1)) -> 40.02 | H11: 42.13 | I11: 40.02
A12: *10011 | B12: LINHO HADES (PROMOCIONAL) | D12: 2.9 | E12: =SUM(H12-(H12*Capa!$C$1)) -> 44.04 | F12: =SUM(I12-(I12*Capa!$C$1)) -> 41.83 | H12: 44.04 | I12: 41.83
A13: *10012 | B13: LINHO HERMES (PROMOCIONAL) | D13: 2.9 | E13: =SUM(H13-(H13*Capa!$C$1)) -> 46.68 | F13: =SUM(I13-(I13*Capa!$C$1)) -> 44.34 | H13: 46.68 | I13: 44.34
A14: *10013 | B14: LINHO CALABRIA (PROMOCIONAL) | D14: 2.9 | E14: =SUM(H14-(H14*Capa!$C$1)) -> 38.78 | F14: =SUM(I14-(I14*Capa!$C$1)) -> 36.84 | H14: 38.78 | I14: 36.84
A15: 10014 | B15: LINHO NEPAL | D15: 3 | E15: =SUM(H15-(H15*Capa!$C$1)) -> 43.55 | F15: =SUM(I15-(I15*Capa!$C$1)) -> 40.42 | H15: 43.55 | I15: 40.42
A16: *10015 | B16: LINHO ARGEL (PROMOCIONAL) | D16: 3 | E16: =SUM(H16-(H16*Capa!$C$1)) -> 40.14 | F16: =SUM(I16-(I16*Capa!$C$1)) -> 38.13 | H16: 40.14 | I16: 38.13
A17: *10018 | B17: SHANTUNG SELENE (PROMOCIONAL) | D17: 3 | E17: =SUM(H17-(H17*Capa!$C$1)) -> 39.11 | F17: =SUM(I17-(I17*Capa!$C$1)) -> 37.15 | H17: 39.11 | I17: 37.15
A18: 10019 | B18: SHANTUNG EROS | D18: 3 | E18: =SUM(H18-(H18*Capa!$C$1)) -> 46.23 | F18: =SUM(I18-(I18*Capa!$C$1)) -> 44.03 | H18: 46.23 | I18: 44.03
A19: *10022 | B19: ARRASTÃO ZELO (PROMOCIONAL) | D19: 3 | E19: =SUM(H19-(H19*Capa!$C$1)) -> 34.21 | F19: =SUM(I19-(I19*Capa!$C$1)) -> 32.49 | H19: 34.21 | I19: 32.49
A20: *10025 | B20: ARRASTÃO HIPNOS (PROMOCIONAL) | D20: 3 | E20: =SUM(H20-(H20*Capa!$C$1)) -> 48.23 | F20: =SUM(I20-(I20*Capa!$C$1)) -> 45.82 | H20: 48.23 | I20: 45.82
A21: *10027 | B21: LINHO HEBE (PROMOCIONAL) | D21: 2.9 | E21: =SUM(H21-(H21*Capa!$C$1)) -> 38 | F21: =SUM(I21-(I21*Capa!$C$1)) -> 36.1 | H21: 38 | I21: 36.1
A22: *10028 | B22: LINHO ANTEROS (PROMOCIONAL) | D22: 2.9 | E22: =SUM(H22-(H22*Capa!$C$1)) -> 38 | F22: =SUM(I22-(I22*Capa!$C$1)) -> 36.1 | H22: 38 | I22: 36.1
A23: 10029 | B23: LINHO DIONE | D23: 2.9 | E23: =SUM(H23-(H23*Capa!$C$1)) -> 60.93 | F23: =SUM(I23-(I23*Capa!$C$1)) -> 57.89 | H23: 60.93 | I23: 57.89
A24: 10030 | B24: LINHO FINESSE | D24: 2.9 | E24: =SUM(H24-(H24*Capa!$C$1)) -> 50.07 | F24: =SUM(I24-(I24*Capa!$C$1)) -> 47.68 | H24: 50.07 | I24: 47.68
A25: 10032 | B25: LINHO ASTECA | D25: 3 | E25: =SUM(H25-(H25*Capa!$C$1)) -> 42.9 | F25: =SUM(I25-(I25*Capa!$C$1)) -> 40.75 | H25: 42.9 | I25: 40.75
A26: 10033 | B26: LINHO CORDOBA | D26: 3 | E26: =SUM(H26-(H26*Capa!$C$1)) -> 32.88 | F26: =SUM(I26-(I26*Capa!$C$1)) -> 31.24 | H26: 32.88 | I26: 31.24
A27: 10034 | B27: LINHO BELIZE | D27: 3 | E27: =SUM(H27-(H27*Capa!$C$1)) -> 30.18 | F27: =SUM(I27-(I27*Capa!$C$1)) -> 28.57 | H27: 30.18 | I27: 28.57
A28: 10036 | B28: LINHO MACAPÁ | D28: 2.8 | E28: =SUM(H28-(H28*Capa!$C$1)) -> 50.22 | F28: =SUM(I28-(I28*Capa!$C$1)) -> 47.71 | H28: 50.22 | I28: 47.71
A29: 10037 | B29: LINHO SANREMO | D29: 2.9 | E29: =SUM(H29-(H29*Capa!$C$1)) -> 54.27 | F29: =SUM(I29-(I29*Capa!$C$1)) -> 51.56 | H29: 54.27 | I29: 51.56
A30: 10040 | B30: RUSTICO SIBÉRIA | D30: 3 | E30: =SUM(H30-(H30*Capa!$C$1)) -> 15.8 | F30: =SUM(I30-(I30*Capa!$C$1)) -> 15.01 | H30: 15.8 | I30: 15.01
A31: 10041 | B31: RUSTICO ALASCA | D31: 3 | E31: =SUM(H31-(H31*Capa!$C$1)) -> 17.35 | F31: =SUM(I31-(I31*Capa!$C$1)) -> 16.48 | H31: 17.35 | I31: 16.48
A32: 10042 | B32: RÚSTICO APOLO | D32: 3 | E32: =SUM(H32-(H32*Capa!$C$1)) -> 31.85 | F32: =SUM(I32-(I32*Capa!$C$1)) -> 30.26 | H32: 31.85 | I32: 30.26
A33: *10043 | B33: TRICÔ HÓRUS (PROMOCIONAL) (CORES 02,04,06 FORA DE LINHA) | D33: 3 | E33: =SUM(H33-(H33*Capa!$C$1)) -> 55 | F33: =SUM(I33-(I33*Capa!$C$1)) -> 52.25 | H33: 55 | I33: 52.25
A34: 10044 | B34: TELA RAVENNA | D34: 3 | E34: =SUM(H34-(H34*Capa!$C$1)) -> 36.69 | F34: =SUM(I34-(I34*Capa!$C$1)) -> 34.94 | H34: 36.69 | I34: 34.94
A35: 10045 | B35: TELA BELIZE | D35: 3 | E35: =SUM(H35-(H35*Capa!$C$1)) -> 36.69 | F35: =SUM(I35-(I35*Capa!$C$1)) -> 34.94 | H35: 36.69 | I35: 34.94
A36: 10046 | B36: TELA PEQUIM | D36: 3 | E36: =SUM(H36-(H36*Capa!$C$1)) -> 36.69 | F36: =SUM(I36-(I36*Capa!$C$1)) -> 34.94 | H36: 36.69 | I36: 34.94
A37: 10047 | B37: RÚSTICO LÍBIA | D37: 3 | E37: =SUM(H37-(H37*Capa!$C$1)) -> 41.04 | F37: =SUM(I37-(I37*Capa!$C$1)) -> 39.09 | H37: 41.04 | I37: 39.09
A38: 10048 | B38: LINHO CORDONÊ | D38: 3 | E38: =SUM(H38-(H38*Capa!$C$1)) -> 50.74 | F38: =SUM(I38-(I38*Capa!$C$1)) -> 48.2 | H38: 50.74 | I38: 48.2
A39: 10049 | B39: LINHO NICARÁGUA | D39: 3 | E39: =SUM(H39-(H39*Capa!$C$1)) -> 43.21 | F39: =SUM(I39-(I39*Capa!$C$1)) -> 41.16 | H39: 43.21 | I39: 41.16
A40: 10050 | B40: LINHO NIAGARA | D40: 3 | E40: =SUM(H40-(H40*Capa!$C$1)) -> 30.34 | F40: =SUM(I40-(I40*Capa!$C$1)) -> 28.9 | H40: 30.34 | I40: 28.9

Sheet Book 12
A1: BOOK 12
A2: CODIGO | B2: DESCRIÇÃO | D2: LARGURA | E2: CORTE | F2: PEÇA | H2: CORTE | I2: PEÇA
A3: 12000 | B3: RUSTICO FLAME NATURAL | D3: 3 | E3: ='Book 14'!E8 -> 22.45 | F3: ='Book 14'!F8 -> 21.33 | H3: --
A4: 12001 | B4: RUSTICO FLAME LIGHT | D4: 3 | E4: ='Book 14'!E9 -> 18.2 | F4: ='Book 14'!F9 -> 17.29 | H4: --
A5: 12003 | B5: RUSTICO FLAME | D5: 3 | E5: =SUM(H5-(H5*Capa!$C$1)) -> 19.39 | F5: =SUM(I5-(I5*Capa!$C$1)) -> 18.42 | H5: 19.39 | I5: 18.42
A6: 12004 | B6: RUSTICO FLAME PRIME | D6: 3 | E6: =SUM(H6-(H6*Capa!$C$1)) -> 40.95 | F6: =SUM(I6-(I6*Capa!$C$1)) -> 38.9 | H6: 40.95 | I6: 38.9
A7: 12005 | B7: JACQUARD PARIS | D7: 2.8 | E7: =SUM(H7-(H7*Capa!$C$1)) -> 50.06 | F7: =SUM(I7-(I7*Capa!$C$1)) -> 47.67 | H7: 50.06 | I7: 47.67
A8: 12006 | B8: JACQUARD LYON | D8: 2.8 | E8: =SUM(H8-(H8*Capa!$C$1)) -> 50.06 | F8: =SUM(I8-(I8*Capa!$C$1)) -> 47.67 | H8: 50.06 | I8: 47.67
A9: 12007 | B9: JACQUARD NANTES | D9: 2.8 | E9: =SUM(H9-(H9*Capa!$C$1)) -> 50.06 | F9: =SUM(I9-(I9*Capa!$C$1)) -> 47.67 | H9: 50.06 | I9: 47.67
A10: 12008 | B10: JACQUARD ELINE | D10: 2.8 | E10: =SUM(H10-(H10*Capa!$C$1)) -> 50.06 | F10: =SUM(I10-(I10*Capa!$C$1)) -> 47.67 | H10: 50.06 | I10: 47.67
A11: 12009 | B11: JACQUARD RIVIERA | D11: 2.8 | E11: =SUM(H11-(H11*Capa!$C$1)) -> 50.06 | F11: =SUM(I11-(I11*Capa!$C$1)) -> 47.67 | H11: 50.06 | I11: 47.67
A12: 12010 | B12: RUSTICO SAVANA (CORES 03 E 04 FORA DE LINHA) | D12: 2.9 | E12: =SUM(H12-(H12*Capa!$C$1)) -> 39.49 | F12: =SUM(I12-(I12*Capa!$C$1)) -> 37.51 | H12: 39.49 | I12: 37.51
A13: 12011 | B13: RUSTICO SINTÉTICO | D13: 3 | E13: =SUM(H13-(H13*Capa!$C$1)) -> 27.2 | F13: =SUM(I13-(I13*Capa!$C$1)) -> 25.84 | H13: 27.2 | I13: 25.84
A14: 12012 | B14: RUSTICO SINTÉTICO XADREZ | D14: 3 | E14: =SUM(H14-(H14*Capa!$C$1)) -> 26.16 | F14: =SUM(I14-(I14*Capa!$C$1)) -> 24.85 | H14: 26.16 | I14: 24.85
A15: 12014 | B15: TRICO CEARÁ | D15: 3 | E15: =SUM(H15-(H15*Capa!$C$1)) -> 32.28 | F15: =SUM(I15-(I15*Capa!$C$1)) -> 30.67 | H15: 32.28 | I15: 30.67
A16: 12016 | B16: GAZE DE LINHO | D16: 2.8 | E16: ='Book 14'!E10 -> 27.4 | F16: ='Book 14'!F10 -> 26.03 | H16: --
A17: *12017 | B17: LINHO ISTAMBUL (PROMOCIONAL) | D17: 3 | E17: =SUM(H17-(H17*Capa!$C$1)) -> 40.35 | F17: =SUM(I17-(I17*Capa!$C$1)) -> 38.33 | H17: 40.35 | I17: 38.33
A18: 12018 | B18: LINHO CANNES | D18: 3 | E18: =SUM(H18-(H18*Capa!$C$1)) -> 41.16 | F18: =SUM(I18-(I18*Capa!$C$1)) -> 39.1 | H18: 41.16 | I18: 39.1
A19: *12019 | B19: LINHO KALAHARI (PROMOCIONAL) | D19: 3 | E19: =SUM(H19-(H19*Capa!$C$1)) -> 33.93 | F19: =SUM(I19-(I19*Capa!$C$1)) -> 32.23 | H19: 33.93 | I19: 32.23
A20: 12020 | B20: LINHO SELVAGEM | D20: 3 | E20: =SUM(H20-(H20*Capa!$C$1)) -> 31.57 | F20: =SUM(I20-(I20*Capa!$C$1)) -> 30.06 | H20: 31.57 | I20: 30.06
A21: 12022 | B21: LINHO CARRARA | D21: 2.9 | E21: =SUM(H21-(H21*Capa!$C$1)) -> 42.13 | F21: =SUM(I21-(I21*Capa!$C$1)) -> 40.12 | H21: 42.13 | I21: 40.12
A22: *12023 | B22: TAFETÁ LAS VEGAS (PROMOCIONAL) | D22: 3 | E22: =SUM(H22-(H22*Capa!$C$1)) -> 25.41 | F22: =SUM(I22-(I22*Capa!$C$1)) -> 24.14 | H22: 25.41 | I22: 24.14
A23: 12027 | B23: VOIL DUBAI | D23: 3 | E23: =SUM(H23-(H23*Capa!$C$1)) -> 19.3 | F23: =SUM(I23-(I23*Capa!$C$1)) -> 18.33 | H23: 19.3 | I23: 18.33
A24: 12029 | B24: VOIL MATISSE | D24: 2.9 | E24: =SUM(H24-(H24*Capa!$C$1)) -> 30.28 | F24: =SUM(I24-(I24*Capa!$C$1)) -> 28.84 | H24: 30.28 | I24: 28.84
A25: 12030 | B25: VOIL LA PAZ | D25: 2.9 | E25: =SUM(H25-(H25*Capa!$C$1)) -> 37.12 | F25: =SUM(I25-(I25*Capa!$C$1)) -> 35.26 | H25: 37.12 | I25: 35.26
A26: 12031 | B26: VOIL BOGOTÁ | D26: 2.9 | E26: =SUM(H26-(H26*Capa!$C$1)) -> 33.82 | F26: =SUM(I26-(I26*Capa!$C$1)) -> 32.21 | H26: 33.82 | I26: 32.21
A27: *12032 | B27: VOIL VERMONT (PROMOCIONAL) | D27: 3 | E27: =SUM(H27-(H27*Capa!$C$1)) -> 29.34 | F27: =SUM(I27-(I27*Capa!$C$1)) -> 27.84 | H27: 29.34 | I27: 27.84
A28: 12034 | B28: VOIL ATLANTA | D28: 3 | E28: =SUM(H28-(H28*Capa!$C$1)) -> 33.34 | F28: =SUM(I28-(I28*Capa!$C$1)) -> 31.67 | H28: 33.34 | I28: 31.67
A29: 12035 | B29: VOIL SUPER | D29: 3 | E29: =SUM(H29-(H29*Capa!$C$1)) -> 16.86 | F29: =SUM(I29-(I29*Capa!$C$1)) -> 16.01 | H29: 16.86 | I29: 16.01
A30: 12036 | B30: VOIL SELVAGEM | D30: 3 | E30: =SUM(H30-(H30*Capa!$C$1)) -> 25.85 | F30: =SUM(I30-(I30*Capa!$C$1)) -> 24.56 | H30: 25.85 | I30: 24.56
A31: 12037 | B31: VOIL SUIÇO | D31: 3 | E31: =SUM(H31-(H31*Capa!$C$1)) -> 17.56 | F31: =SUM(I31-(I31*Capa!$C$1)) -> 16.69 | H31: 17.56 | I31: 16.69
A32: 12039 | B32: VOIL CRISTAL | D32: 3 | E32: =SUM(H32-(H32*Capa!$C$1)) -> 19.3 | F32: =SUM(I32-(I32*Capa!$C$1)) -> 18.33 | H32: 19.3 | I32: 18.33
A33: 12041 | B33: VOIL DETROIT | D33: 3 | E33: =SUM(H33-(H33*Capa!$C$1)) -> 19.3 | F33: =SUM(I33-(I33*Capa!$C$1)) -> 18.33 | H33: 19.3 | I33: 18.33
A34: *12042 | B34: VOIL DALLAS (PROMOCIONAL) | D34: 3 | E34: =SUM(H34-(H34*Capa!$C$1)) -> 21.86 | F34: =SUM(I34-(I34*Capa!$C$1)) -> 20.77 | H34: 21.86 | I34: 20.77
A35: *12043 | B35: VOIL MONTREAL (PROMOCIONAL) | D35: 3 | E35: =SUM(H35-(H35*Capa!$C$1)) -> 17.62 | F35: =SUM(I35-(I35*Capa!$C$1)) -> 16.74 | H35: 17.62 | I35: 16.74
A36: 12044 | B36: RÚSTICO FLAME NACIONAL | D36: 3 | E36: =SUM(H36-(H36*Capa!$C$1)) -> 23.74 | F36: =SUM(I36-(I36*Capa!$C$1)) -> 22.55 | H36: 23.74 | I36: 22.55
A37: 12045 | B37: RÚSTICO ARIZONA | D37: 3 | E37: =SUM(H37-(H37*Capa!$C$1)) -> 32.99 | F37: =SUM(I37-(I37*Capa!$C$1)) -> 31.34 | H37: 32.99 | I37: 31.34
A38: 12046 | B38: GAZE COSTA RICA | D38: 3 | E38: =SUM(H38-(H38*Capa!$C$1)) -> 23.67 | F38: =SUM(I38-(I38*Capa!$C$1)) -> 22.54 | H38: 23.67 | I38: 22.54
A39: 12047 | B39: VOIL NEVADA | D39: 2.8 | E39: =SUM(H39-(H39*Capa!$C$1)) -> 26.68 | F39: =SUM(I39-(I39*Capa!$C$1)) -> 25.34 | H39: 26.68 | I39: 25.34
A40: 12048 | B40: VOIL CHIFFON VIENA | D40: 3 | E40: =SUM(H40-(H40*Capa!$C$1)) -> 17.6 | F40: =SUM(I40-(I40*Capa!$C$1)) -> 18.53 | H40: 17.6 | I40: 18.53
...

Sheet Book 13
A1: BOOK 13
A2: CODIGO | B2: DESCRIÇÃO | D2: LARGURA | E2: CORTE | F2: PEÇA | H2: CORTE | I2: PEÇA
A3: *13000 | B3: LINHO HERMES (PROMOCIONAL) | D3: 2.9 | E3: =SUM(H3-(H3*Capa!$C$1)) -> 44.68 | F3: =SUM(I3-(I3*Capa!$C$1)) -> 44.34 | H3: 44.68 | I3: 44.34
A4: 13001 | B4: PIQUET 2,50 MTS | D4: 2.5 | E4: =SUM(H4-(H4*Capa!$C$1)) -> 39.2 | F4: =SUM(I4-(I4*Capa!$C$1)) -> 37.2 | H4: 39.2 | I4: 37.2
A5: 13001 | B5: PIQUET 1,40 MTS | D5: 1.4 | E5: =SUM(H5-(H5*Capa!$C$1)) -> 52.7 | F5: =SUM(I5-(I5*Capa!$C$1)) -> 50.06 | H5: 52.7 | I5: 50.06
A6: *13002 | B6: LINHO VILA REAL (PROMOCIONAL) | D6: 2.9 | E6: =SUM(H6-(H6*Capa!$C$1)) -> 44.84 | F6: =SUM(I6-(I6*Capa!$C$1)) -> 42.59 | H6: 44.84 | I6: 42.59
A7: *13003 | B7: JACQUARD CATAR (PROMOCIONAL) | D7: 1.45 | E7: =SUM(H7-(H7*Capa!$C$1)) -> 49.14 | F7: =SUM(I7-(I7*Capa!$C$1)) -> 46.68 | H7: 49.14 | I7: 46.68
A8: *13004 | B8: TRICO HORUS (PROMOCIONAL) | D8: 3 | E8: =SUM(H8-(H8*Capa!$C$1)) -> 55 | F8: =SUM(I8-(I8*Capa!$C$1)) -> 52.25 | H8: 55 | I8: 52.25
A9: *13005 | B9: JACQUARD JAIPUR (PROMOCIONAL) | D9: 1.45 | E9: =SUM(H9-(H9*Capa!$C$1)) -> 62.64 | F9: =SUM(I9-(I9*Capa!$C$1)) -> 59.51 | H9: 62.64 | I9: 59.51
A10: *13006 | B10: JACQUARD ESTOCOMO (PROMOCIONAL) | D10: 1.45 | E10: =SUM(H10-(H10*Capa!$C$1)) -> 55.49 | F10: =SUM(I10-(I10*Capa!$C$1)) -> 52.72 | H10: 55.49 | I10: 52.72
A11: *13007 | B11: SEDA BALI LISO (PROMOCIONAL) | D11: 3 | E11: =SUM(H11-(H11*Capa!$C$1)) -> 39.76 | F11: =SUM(I11-(I11*Capa!$C$1)) -> 37.77 | H11: 39.76 | I11: 37.77
A12: *13008 | B12: SHANTUNG SELENE (PROMOCIONAL) | D12: 3 | E12: =SUM(H12-(H12*Capa!$C$1)) -> 39.11 | F12: =SUM(I12-(I12*Capa!$C$1)) -> 37.15 | H12: 39.11 | I12: 37.15
A13: 13009 | B13: TRICO PETRA | D13: 3 | E13: =SUM(H13-(H13*Capa!$C$1)) -> 36.69 | F13: =SUM(I13-(I13*Capa!$C$1)) -> 34.94 | H13: 36.69 | I13: 34.94
A14: 13010 | B14: SHANTUNG CLASSICO LISO | D14: 2.9 | E14: =SUM(H14-(H14*Capa!$C$1)) -> 63.7 | F14: =SUM(I14-(I14*Capa!$C$1)) -> 60.51 | H14: 63.7 | I14: 60.51
A15: 13011 | B15: SHANTUNG MALTA | D15: 2.9 | E15: =SUM(H15-(H15*Capa!$C$1)) -> 75.3 | F15: =SUM(I15-(I15*Capa!$C$1)) -> 71.53 | H15: 75.3 | I15: 71.53
A16: *13012 | B16: VOIL FUJI (PROMOCIONAL) | D16: 2.9 | E16: =SUM(H16-(H16*Capa!$C$1)) -> 52.41 | F16: =SUM(I16-(I16*Capa!$C$1)) -> 49.79 | H16: 52.41 | I16: 49.79
A17: *13013 | B17: VOIL TÓQUIO (PROMOCIONAL) | D17: 2.9 | E17: =SUM(H17-(H17*Capa!$C$1)) -> 63.78 | F17: =SUM(I17-(I17*Capa!$C$1)) -> 60.59 | H17: 63.78 | I17: 60.59
A18: 13014 | B18: LINHO HIMALAIA | D18: 3 | E18: =SUM(H18-(H18*Capa!$C$1)) -> 54.07 | F18: =SUM(I18-(I18*Capa!$C$1)) -> 51.5 | H18: 54.07 | I18: 51.5
A19: 13015 | B19: RUSTICO OREGON | D19: 2.8 | E19: =SUM(H19-(H19*Capa!$C$1)) -> 70.4 | F19: =SUM(I19-(I19*Capa!$C$1)) -> 66.88 | H19: 70.4 | I19: 66.88
A20: 13016 | B20: LINHO ÉTNA | D20: 2.9 | E20: =SUM(H20-(H20*Capa!$C$1)) -> 40.9 | F20: =SUM(I20-(I20*Capa!$C$1)) -> 38.86 | H20: 40.9 | I20: 38.86
A21: *13017 | B21: LINHO IBIZA (PROMOCIONAL) | D21: 3 | E21: =SUM(H21-(H21*Capa!$C$1)) -> 79.59 | F21: =SUM(I21-(I21*Capa!$C$1)) -> 75.61 | H21: 79.59 | I21: 75.61
A22: *13018 | B22: LINHO DACAR (PROMOCIONAL) | D22: 2.9 | E22: =SUM(H22-(H22*Capa!$C$1)) -> 79.59 | F22: =SUM(I22-(I22*Capa!$C$1)) -> 75.61 | H22: 79.59 | I22: 75.61
A23: *13019 | B23: LINHO ORIENTAL (PROMOCIONAL) | D23: 3 | E23: =SUM(H23-(H23*Capa!$C$1)) -> 52.91 | F23: =SUM(I23-(I23*Capa!$C$1)) -> 50.26 | H23: 52.91 | I23: 50.26
A24: *13020 | B24: LINHO COLISEU (PROMOCIONAL) | D24: 2.9 | E24: =SUM(H24-(H24*Capa!$C$1)) -> 61.04 | F24: =SUM(I24-(I24*Capa!$C$1)) -> 57.99 | H24: 61.04 | I24: 57.99
A25: 13021 | B25: LINHO MANHATTAN | D25: 3 | E25: =SUM(H25-(H25*Capa!$C$1)) -> 73.9 | F25: =SUM(I25-(I25*Capa!$C$1)) -> 65.84 | H25: 73.9 | I25: 65.84
A26: 13022 | B26: LINHO ATACAMA | D26: 3 | E26: =SUM(H26-(H26*Capa!$C$1)) -> 37.14 | F26: =SUM(I26-(I26*Capa!$C$1)) -> 35.29 | H26: 37.14 | I26: 35.29
A27: *13023 | B27: LINHO SAFIRA (PROMOCIONAL) | D27: 2.95 | E27: =SUM(H27-(H27*Capa!$C$1)) -> 54.57 | F27: =SUM(I27-(I27*Capa!$C$1)) -> 51.84 | H27: 54.57 | I27: 51.84
A28: 13024 | B28: CAMURÇA DUBLIN | D28: 2.9 | E28: =SUM(H28-(H28*Capa!$C$1)) -> 46.96 | F28: =SUM(I28-(I28*Capa!$C$1)) -> 44.61 | H28: 46.96 | I28: 44.61
A29: *13025 | B29: LINHO SENEGAL (PROMOCIONAL) | D29: 2.95 | E29: =SUM(H29-(H29*Capa!$C$1)) -> 41.5 | F29: =SUM(I29-(I29*Capa!$C$1)) -> 39.43 | H29: 41.5 | I29: 39.43
A30: *13026 | B30: VOIL BELGICA (PROMOCIONAL) | D30: 2.9 | E30: =SUM(H30-(H30*Capa!$C$1)) -> 65.2 | F30: =SUM(I30-(I30*Capa!$C$1)) -> 61.94 | H30: 65.2 | I30: 61.94
A31: *13027 | B31: SHANTUNG MIAMI (PROMOCIONAL) | D31: 2.9 | E31: =SUM(H31-(H31*Capa!$C$1)) -> 76.5 | F31: =SUM(I31-(I31*Capa!$C$1)) -> 72.68 | H31: 76.5 | I31: 72.68
A32: *13028 | B32: SHANTUNG EVEREST (PROMOCIONAL) | D32: 2.9 | E32: =SUM(H32-(H32*Capa!$C$1)) -> 59.28 | F32: =SUM(I32-(I32*Capa!$C$1)) -> 56.33 | H32: 59.28 | I32: 56.33
A33: *13029 | B33: SHANTUNG VILLAGE (PROMOCIONAL) | D33: 2.9 | E33: =SUM(H33-(H33*Capa!$C$1)) -> 65.9 | F33: =SUM(I33-(I33*Capa!$C$1)) -> 62.6 | H33: 65.9 | I33: 62.6
A34: *13030 | B34: SHANTUNG CLASSICO LISTRADO (PROMOCIONAL) | D34: 2.9 | E34: =SUM(H34-(H34*Capa!$C$1)) -> 49.14 | F34: =SUM(I34-(I34*Capa!$C$1)) -> 46.68 | H34: 49.14 | I34: 46.68

Sheet Book 14
A1: BOOK 14
A2: CODIGO | B2: DESCRIÇÃO | D2: LARGURA | E2: CORTE | F2: PEÇA | H2: CORTE | I2: PEÇA
A3: 14000 | B3: TELA PICASSO | D3: 3 | E3: ='Book 13'!E13 -> 36.69 | F3: ='Book 13'!F13 -> 34.94 | H3: --
A4: 14001 | B4: VOIL TRICO | D4: 3 | E4: =SUM(H4-(H4*Capa!$C$1)) -> 32.28 | F4: =SUM(I4-(I4*Capa!$C$1)) -> 30.67 | H4: 32.28 | I4: 30.67
A5: 14002 | B5: VOIL LINHO EGITO | D5: 2.8 | E5: =SUM(H5-(H5*Capa!$C$1)) -> 35.97 | F5: =SUM(I5-(I5*Capa!$C$1)) -> 34.17 | H5: 35.97 | I5: 34.17
A6: 14003 | B6: VOIL DAMASCO | D6: 3 | E6: =SUM(H6-(H6*Capa!$C$1)) -> 29.35 | F6: =SUM(I6-(I6*Capa!$C$1)) -> 27.88 | H6: 29.35 | I6: 27.88
A7: 14004 | B7: VOIL LUXOR | D7: 3 | E7: =SUM(H7-(H7*Capa!$C$1)) -> 40.95 | F7: =SUM(I7-(I7*Capa!$C$1)) -> 38.9 | H7: 40.95 | I7: 38.9
A8: 14005 | B8: VOIL LEDA RUSTICO | D8: 2.8 | E8: =SUM(H8-(H8*Capa!$C$1)) -> 22.45 | F8: =SUM(I8-(I8*Capa!$C$1)) -> 21.33 | H8: 22.45 | I8: 21.33
A9: 14006 | B9: VOIL LEDA | D9: 3 | E9: =SUM(H9-(H9*Capa!$C$1)) -> 18.2 | F9: =SUM(I9-(I9*Capa!$C$1)) -> 17.29 | H9: 18.2 | I9: 17.29
A10: 14007 | B10: VOIL GAZE DE LINHO | D10: 2.8 | E10: =SUM(H10-(H10*Capa!$C$1)) -> 27.4 | F10: =SUM(I10-(I10*Capa!$C$1)) -> 26.03 | H10: 27.4 | I10: 26.03
A11: 14009 | B11: VOIL LINHO NATURE | D11: 2.8 | E11: =SUM(H11-(H11*Capa!$C$1)) -> 28.56 | F11: =SUM(I11-(I11*Capa!$C$1)) -> 27.13 | H11: 28.56 | I11: 27.13
A12: 14010 | B12: VOIL SHANTUNG LINEN | D12: 2.8 | E12: =SUM(H12-(H12*Capa!$C$1)) -> 38.53 | F12: =SUM(I12-(I12*Capa!$C$1)) -> 36.6 | H12: 38.53 | I12: 36.6
A13: 14011 | B13: VOIL PERSA | D13: 3 | E13: =SUM(H13-(H13*Capa!$C$1)) -> 27.94 | F13: =SUM(I13-(I13*Capa!$C$1)) -> 26.61 | H13: 27.94 | I13: 26.61
A14: 14012 | B14: VOIL DOLLY | D14: 2.8 | E14: =SUM(H14-(H14*Capa!$C$1)) -> 15.48 | F14: =SUM(I14-(I14*Capa!$C$1)) -> 14.71 | H14: 15.48 | I14: 14.71
A15: 14013 | B15: VOIL CHIFFON LISO | D15: 2.8 | E15: =SUM(H15-(H15*Capa!$C$1)) -> 17.6 | F15: =SUM(I15-(I15*Capa!$C$1)) -> 18.53 | H15: 17.6 | I15: 18.53
... A28: 14026 | B28: BLACK-OUT TECIDO CAIRO | D28: 2.8 | E28: =SUM(H28-(H28*Capa!$C$1)) -> 67.22 | F28: =SUM(I28-(I28*Capa!$C$1)) -> 63.86 | H28: 67.22 | I28: 63.86
A29: 14027 | B29: BLACK-OUT TECIDO 2,80L | D29: 2.8 | E29: ='Book 15'!E12 -> 25.29 | F29: ='Book 15'!F12 -> 24.02 | H29: --
A30: 14028 | B30: MICROFIBRA 100G 3,00L | D30: 3 | E30: =SUM(H30-(H30*Capa!$C$1)) -> 14.98 | F30: =SUM(I30-(I30*Capa!$C$1)) -> 14.23 | H30: 14.98 | I30: 14.23
A31: 14029 | B31: MICROFIBRA 65G 3,00L | D31: 3 | E31: ='Book 15'!E15 -> 9.61 | F31: ='Book 15'!F15 -> 9.12 | H31: --
A32: 14030 | B32: MICROFIBRA 65G 2,80L | D32: 2.8 | E32: ='Book 15'!E14 -> 9 | F32: ='Book 15'!F14 -> 8.56 | H32: --

Sheet Book 15
A1: BOOK 15
A2: CODIGO | B2: DESCRIÇÃO | D2: LARGURA | E2: CORTE | F2: PEÇA | H2: CORTE | I2: PEÇA
A3: 15000 | B3: BLACK-OUT BRISTOL | D3: 2.8 | E3: =SUM(H3-(H3*Capa!$C$1)) -> 54.07 | F3: =SUM(I3-(I3*Capa!$C$1)) -> 51.5 | H3: 54.07 | I3: 51.5
A4: 15001 | B4: BLACK-OUT MELBOURN | D4: 2.8 | E4: =SUM(H4-(H4*Capa!$C$1)) -> 93.74 | F4: =SUM(I4-(I4*Capa!$C$1)) -> 89.05 | H4: 93.74 | I4: 89.05
A5: 15002 | B5: BLACK-OUT SUNSHINE | D5: 2.8 | E5: =SUM(H5-(H5*Capa!$C$1)) -> 91.93 | F5: =SUM(I5-(I5*Capa!$C$1)) -> 87.33 | H5: 91.93 | I5: 87.33
A6: 15003 | B6: BLACK-OUT ATENAS | D6: 2.8 | E6: =SUM(H6-(H6*Capa!$C$1)) -> 99.16 | F6: =SUM(I6-(I6*Capa!$C$1)) -> 94.2 | H6: 99.16 | I6: 94.2
A7: 15004 | B7: BLACK-OUT KAIRO | D7: 2.8 | E7: =SUM(H7-(H7*Capa!$C$1)) -> 94.64 | F7: =SUM(I7-(I7*Capa!$C$1)) -> 89.94 | H7: 94.64 | I7: 89.94
A8: 15005 | B8: BLACK-OUT MALI | D8: 2.8 | E8: =SUM(H8-(H8*Capa!$C$1)) -> 72.71 | F8: =SUM(I8-(I8*Capa!$C$1)) -> 69.07 | H8: 72.71 | I8: 69.07
A9: 15006 | B9: BLACK-OUT MALI LIGHT | D9: 2.8 | E9: =SUM(H9-(H9*Capa!$C$1)) -> 35.66 | F9: =SUM(I9-(I9*Capa!$C$1)) -> 33.97 | H9: 35.66 | I9: 33.97
A10: 15007 | B10: BLACK-OUT ACAPULCO | D10: 2.8 | E10: =SUM(H10-(H10*Capa!$C$1)) -> 68.24 | F10: =SUM(I10-(I10*Capa!$C$1)) -> 64.83 | H10: 68.24 | I10: 64.83
A11: 15008 | B11: BLACK-OUT ATACAMA | D11: 3 | E11: =SUM(H11-(H11*Capa!$C$1)) -> 55.45 | F11: =SUM(I11-(I11*Capa!$C$1)) -> 52.68 | H11: 55.45 | I11: 52.68
A12: 15009 | B12: BLACK-OUT TECIDO 2,80 MTS | D12: 2.8 | E12: =SUM(H12-(H12*Capa!$C$1)) -> 25.29 | F12: =SUM(I12-(I12*Capa!$C$1)) -> 24.02 | H12: 25.29 | I12: 24.02
A13: 15010 | B13: BLACK-OUT TECIDO 3,00 MTS | D13: 3 | E13: =SUM(H13-(H13*Capa!$C$1)) -> 28.08 | F13: =SUM(I13-(I13*Capa!$C$1)) -> 27.63 | H13: 28.08 | I13: 27.63
A14: 15011 | B14: FORRO MICROFIBRA 2,80 MTS | D14: 2.8 | E14: =SUM(H14-(H14*Capa!$C$1)) -> 9 | F14: =SUM(I14-(I14*Capa!$C$1)) -> 8.56 | H14: 9 | I14: 8.56
... A27: 14021 | B27: BLACK-OUT SUPER BLACK LISO PRETO | D27: 2.8 | E27: =SUM(H27-(H27*Capa!$C$1)) -> 33.05 | F27: =SUM(I27-(I27*Capa!$C$1)) -> 31.4 | H27: 33.05 | I27: 31.4

Sheet Book 16
A1: BOOK 16
A2: CODIGO | B2: DESCRIÇÃO | D2: LARGURA | E2: CORTE | F2: PEÇA | H2: CORTE | I2: PEÇA
A3: 16000 | B3: GRANADO | D3: 3 | E3: =SUM(H3-(H3*Capa!$C$1)) -> 21.48 | F3: =SUM(I3-(I3*Capa!$C$1)) -> 20.46 | H3: 21.48 | I3: 20.46
A4: 16001 | B4: GRANITÉ | D4: 3 | E4: =SUM(H4-(H4*Capa!$C$1)) -> 21.48 | F4: =SUM(I4-(I4*Capa!$C$1)) -> 20.46 | H4: 21.48 | I4: 20.46
A5: 16002 | B5: OXFORD | D5: 3 | E5: =SUM(H5-(H5*Capa!$C$1)) -> 16.96 | F5: =SUM(I5-(I5*Capa!$C$1)) -> 16.15 | H5: 16.96 | I5: 16.15
A6: 16003 | B6: VELUDO | D6: 2.8 | E6: =SUM(H6-(H6*Capa!$C$1)) -> 31.49 | F6: =SUM(I6-(I6*Capa!$C$1)) -> 29.99 | H6: 31.49 | I6: 29.99
A7: 16004 | B7: SARJA | D7: 2.8 | E7: =SUM(H7-(H7*Capa!$C$1)) -> 36.19 | F7: =SUM(I7-(I7*Capa!$C$1)) -> 34.38 | H7: 36.19 | I7: 34.38
A8: 16005 | B8: MALAGA | D8: 3 | E8: =SUM(H8-(H8*Capa!$C$1)) -> 19.92 | F8: =SUM(I8-(I8*Capa!$C$1)) -> 18.97 | H8: 19.92 | I8: 18.97
A9: 16006 | B9: GUANABARA | D9: 3 | E9: =SUM(H9-(H9*Capa!$C$1)) -> 33.46 | F9: =SUM(I9-(I9*Capa!$C$1)) -> 31.78 | H9: 33.46 | I9: 31.78
A10: 16007 | B10: CETIM LISO | D10: 3 | E10: =SUM(H10-(H10*Capa!$C$1)) -> 22.8 | F10: =SUM(I10-(I10*Capa!$C$1)) -> 21.71 | H10: 22.8 | I10: 21.71
A11: 16008 | B11: PIQUET | D11: 2.5 | E11: =SUM(H11-(H11*Capa!$C$1)) -> 39.2 | F11: =SUM(I11-(I11*Capa!$C$1)) -> 37.24 | H11: 39.2 | I11: 37.24
A12: 16009 | B12: GORGURINHO | D12: 2.8 | E12: =SUM(H12-(H12*Capa!$C$1)) -> 33.27 | F12: =SUM(I12-(I12*Capa!$C$1)) -> 32.59 | H12: 33.27 | I12: 32.59
A13: 16010 | B13: BRISTOL | D13: 2.8 | E13: =SUM(H13-(H13*Capa!$C$1)) -> 35.97 | F13: =SUM(I13-(I13*Capa!$C$1)) -> 34.17 | H13: 35.97 | I13: 34.17
A14: 16011 | B14: PANAMA | D14: 2.8 | E14: =SUM(H14-(H14*Capa!$C$1)) -> 35.97 | F14: =SUM(I14-(I14*Capa!$C$1)) -> 34.17 | H14: 35.97 | I14: 34.17
... A20: 16017 | B20: JACQUARD MEDALHÃO | D20: 2.8 | E20: =SUM(H20-(H20*Capa!$C$1)) -> 35.97 | F20: =SUM(I20-(I20*Capa!$C$1)) -> 34.17 | H20: 35.97 | I20: 34.17

Sheet Trilho Motorizado
A2: TRILHO MOTORIZADO NA COR BRANCA/PRETA COM CONTROLE DE 1 CANAL
A3: 5 ANOS DE GARANTIA
A4: ACESSÓRIOS PARA MONTAGEM NA MEDIDA ESCOLHIDA INCLUSOS
A5: *MODELO WAVE PLUS NÃO ACOMPANHA A ENTRETELA QUE DEVE SER ADQUIRIDA SEPARADAMENTE
A6: *MODELO WAVE BOTÃO NÃO ACOMPANHA A FITA QUE DEVE SER ADQUIRIDA SEPARADAMENTE
A7: ESPECIFICAÇÕES TECNICAS | B7: MEDIDA | C7: FRANZIDO | E7: WAVE PLUS* | G7: WAVE BOTÃO* | J7: MEDIDA | K7: FRANZIDO | L7: WAVE PLUS | M7: WAVE BOTÃO
A8: -MOTOR BIVOLT COM 2NM -CARREGA ATÉ 100KG COM 2 METROS DE TRILHO E 45KG COM 12 METROS DE TRILHO -WIFI, RF 433,92 MHZ E CONTATO LÓGICO -APLICATIVO DISPONÍVEL PARA SMARTPHONE ANDROID E IOS -MOTOR SILENCIOSO, RODÍZIOS COM RODAS PARA MENOR ATRITO NO TRILHO -CONEXÃO PARA AUTOMAÇÃO COM CONTROLE POR VOZ (ALEXA E GOOGLE ASSISTENTE) -FIM DE CURSO SUAVE -ACIONAMENTO AUTOMÁTICO AO PUXAR A CORTINA | B8: ATÉ 1,00 | C8: =SUM(K8-(K8*Capa!$C$1)) -> 1020.83 | E8: =SUM(L8-(L8*Capa!$C$1)) -> 1043.48 | G8: =SUM(M8-(M8*Capa!$C$1)) -> 1048.02 | J8: ATÉ 1,00 | K8: 1020.83 | L8: 1043.48 | M8: 1048.02
B9: 1,01 a 1,50 | C9: =SUM(K9-(K9*Capa!$C$1)) -> 1086.37 | E9: =SUM(L9-(L9*Capa!$C$1)) -> 1098.86 | G9: =SUM(M9-(M9*Capa!$C$1)) -> 1124.75 | J9: 1,01 a 1,50 | K9: 1086.37 | L9: 1098.86 | M9: 1124.75
B10: 1,51 a 2,00 | C10: =SUM(K10-(K10*Capa!$C$1)) -> 1151.91 | E10: =SUM(L10-(L10*Capa!$C$1)) -> 1154.25 | G10: =SUM(M10-(M10*Capa!$C$1)) -> 1201.49 | J10: 1,51 a 2,00 | K10: 1151.91 | L10: 1154.25 | M10: 1201.49
B11: 2,01 a 2,50 | C11: =SUM(K11-(K11*Capa!$C$1)) -> 1158.78 | E11: =SUM(L11-(L11*Capa!$C$1)) -> 1189.63 | G11: =SUM(M11-(M11*Capa!$C$1)) -> 1260.99 | J11: 2,01 a 2,50 | K11: 1158.78 | L11: 1189.63 | M11: 1260.99
B12: 2,51 a 3,00 | C12: =SUM(K12-(K12*Capa!$C$1)) -> 1207.05 | E12: =SUM(L12-(L12*Capa!$C$1)) -> 1245.02 | G12: =SUM(M12-(M12*Capa!$C$1)) -> 1320.5 | J12: 2,51 a 3,00 | K12: 1207.05 | L12: 1245.02 | M12: 1320.5
B13: 3,01 a 3,50 | C13: =SUM(K13-(K13*Capa!$C$1)) -> 1251.07 | E13: =SUM(L13-(L13*Capa!$C$1)) -> 1290.08 | G13: =SUM(M13-(M13*Capa!$C$1)) -> 1374.87 | J13: 3,01 a 3,50 | K13: 1251.07 | L13: 1290.08 | M13: 1374.87
B14: 3,51 a 4,00 | C14: =SUM(K14-(K14*Capa!$C$1)) -> 1295.09 | E14: =SUM(L14-(L14*Capa!$C$1)) -> 1335.15 | G14: =SUM(M14-(M14*Capa!$C$1)) -> 1429.25 | J14: 3,51 a 4,00 | K14: 1295.09 | L14: 1335.15 | M14: 1429.25
B15: 4,01 a 4,50 | C15: =SUM(K15-(K15*Capa!$C$1)) -> 1346.96 | E15: =SUM(L15-(L15*Capa!$C$1)) -> 1388.62 | G15: =SUM(M15-(M15*Capa!$C$1)) -> 1491.67 | J15: 4,01 a 4,50 | K15: 1346.96 | L15: 1388.62 | M15: 1491.67
B16: 4,51 a 5,00 | C16: =SUM(K16-(K16*Capa!$C$1)) -> 1394.95 | E16: =SUM(L16-(L16*Capa!$C$1)) -> 1438.1 | G16: =SUM(M16-(M16*Capa!$C$1)) -> 1554.1 | J16: 4,51 a 5,00 | K16: 1394.95 | L16: 1438.1 | M16: 1554.1
B17: 5,01 a 5,50 | C17: =SUM(K17-(K17*Capa!$C$1)) -> 1493.58 | E17: =SUM(L17-(L17*Capa!$C$1)) -> 1524.07 | G17: =SUM(M17-(M17*Capa!$C$1)) -> 1615.42 | J17: 5,01 a 5,50 | K17: 1493.58 | L17: 1524.07 | M17: 1615.42
B18: 5,51 a 6,00 | C18: =SUM(K18-(K18*Capa!$C$1)) -> 1577.8 | E18: =SUM(L18-(L18*Capa!$C$1)) -> 1610.05 | G18: =SUM(M18-(M18*Capa!$C$1)) -> 1674.75 | J18: 5,51 a 6,00 | K18: 1577.8 | L18: 1610.05 | M18: 1674.75
B19: 6,01 a 6,50 | C19: =SUM(K19-(K19*Capa!$C$1)) -> 1648.86 | E19: =SUM(L19-(L19*Capa!$C$1)) -> 1682.52 | G19: =SUM(M19-(M19*Capa!$C$1)) -> 1755.02 | J19: 6,01 a 6,50 | K19: 1648.86 | L19: 1682.52 | M19: 1755.02
B20: 6,51 a 7,00 | C20: =SUM(K20-(K20*Capa!$C$1)) -> 1719.9 | E20: =SUM(L20-(L20*Capa!$C$1)) -> 1755 | G20: =SUM(M20-(M20*Capa!$C$1)) -> 1835.3 | J20: 6,51 a 7,00 | K20: 1719.9 | L20: 1755 | M20: 1835.3
... B30: 11,51 a 12,00 | C30: =SUM(K30-(K30*Capa!$C$1)) -> 2145.8 | E30: =SUM(L30-(L30*Capa!$C$1)) -> 2189.6 | G30: =SUM(M30-(M30*Capa!$C$1)) -> 2426.1 | J30: 11,51 a 12,00 | K30: 2145.8 | L30: 2189.6 | M30: 2426.1
A31: ACESSÓRIOS | J31: ACESSÓRIOS
A32: CONTROLE REMOTO DE 1 CANAL | G32: =SUM(J32-(J32*Capa!$C$1)) -> 80 | J32: 80
A33: CONTROLE REMOTO DE 2 CANAIS | G33: =SUM(J33-(J33*Capa!$C$1)) -> 120 | J33: 120
A34: CONTROLE REMOTO DE 15 CANAIS | G34: =SUM(J34-(J34*Capa!$C$1)) -> 160 | J34: 160
A35: TROCA DE CONTROLE PARA 2 CANAIS | G35: =SUM(J35-(J35*Capa!$C$1)) -> 40 | J35: 40
A36: CURVA 90º DE PVC | G36: =SUM(J36-(J36*Capa!$C$1)) -> 50 | J36: 50
A37: CURVATURA NO PROPRIO TRILHO ( NECESSITA MOLDE ) | G37: =SUM(J37) -> 249 | J37: 249
A38: ENTRETELA WAVE PLUS (POR METRO) | G38: ='Wave-Square-Retangular'!F46 -> 7.85 | J38: --
A39: FITA WAVE ( 2X1, 2,5X1, 3X1, 3,5X1, 4X1) (POR METRO) (BRANCO, BEGE, KAKI,CINZA, PRETO) | G39: ='Wave-Square-Retangular'!F47 -> 6.97 | J39: --
A40: CLIPS (UNIDADE) | G40: =Trilhos!D35 -> 0.19 | J40: --
A41: TRILHOS ACIMA DE 6MTS SERÁ ENVIADO COM EMENDA NO TRILHO (EMENDA INCLUSA)
A42: PRAZO DE ENTREGA: 7 DIAS PARA TRILHOS NOVOS E 5 DIAS PARA CONSERTO
A43: FAVOR INFORMAR O MODELO DE ABERTURA

Sheet Varão Prime Montado
A2: VARÃO PRIME MONTADO COM ACIONAMENTO
A3: CORES: CROMADO, AÇO ESCOVADO, BRANCO, PRETO,DOURADO,OURO VELHO E OURO ROSE
A4: MEDIDA | B4: 2 X 1 | C4: 2,5 X 1 | D4: 3 X 1 | E4: 3,5 X 1 | F4: 4 X 1 | G4: S/ FITA | H4: WAVE PLUS | I4: FRANZIDO | K4: MEDIDA | L4: 2 X 1 | M4: 2,5 X 1 | N4: 3 X 1 | O4: 3,5 X 1 | P4: 4 X 1 | Q4: S/ FITA | R4: WAVE PLUS | S4: FRANZIDO
A5: ATÉ 1,00 | B5: =SUM(L5-(L5*Capa!$C$1)) -> 95.984 | C5: =SUM(M5-(M5*Capa!$C$1)) -> 99.469 | D5: =SUM(N5-(N5*Capa!$C$1)) -> 102.954 | E5: =SUM(O5-(O5*Capa!$C$1)) -> 106.439 | F5: =SUM(P5-(P5*Capa!$C$1)) -> 109.924 | G5: =SUM(Q5-(Q5*Capa!$C$1)) -> 82.044 | H5: =SUM(R5-(R5*Capa!$C$1)) -> 82.044 | I5: =SUM(S5-(S5*Capa!$C$1)) -> 70.81 | K5: ATÉ 1,00 | L5: 95.984 | M5: 99.469 | N5: 102.954 | O5: 106.439 | P5: 109.924 | Q5: 82.044 | R5: 82.044 | S5: 70.81
A6: ATÉ 1,50 | B6: =SUM(L6-(L6*Capa!$C$1)) -> 120.107 | C6: =SUM(M6-(M6*Capa!$C$1)) -> 125.3345 | D6: =SUM(N6-(N6*Capa!$C$1)) -> 130.562 | E6: =SUM(O6-(O6*Capa!$C$1)) -> 135.7895 | F6: =SUM(P6-(P6*Capa!$C$1)) -> 141.017 | G6: =SUM(Q6-(Q6*Capa!$C$1)) -> 99.197 | H6: =SUM(R6-(R6*Capa!$C$1)) -> 99.197 | I6: =SUM(S6-(S6*Capa!$C$1)) -> 86.33 | K6: ATÉ 1,50 | L6: 120.107 | M6: 125.3345 | N6: 130.562 | O6: 135.7895 | P6: 141.017 | Q6: 99.197 | R6: 99.197 | S6: 86.33
A7: ATÉ 2,00 | B7: =SUM(L7-(L7*Capa!$C$1)) -> 145.45 | C7: =SUM(M7-(M7*Capa!$C$1)) -> 152.42 | D7: =SUM(N7-(N7*Capa!$C$1)) -> 159.39 | E7: =SUM(O7-(O7*Capa!$C$1)) -> 166.36 | F7: =SUM(P7-(P7*Capa!$C$1)) -> 173.33 | G7: =SUM(Q7-(Q7*Capa!$C$1)) -> 117.57 | H7: =SUM(R7-(R7*Capa!$C$1)) -> 117.57 | I7: =SUM(S7-(S7*Capa!$C$1)) -> 101.85 | K7: ATÉ 2,00 | L7: 145.45 | M7: 152.42 | N7: 159.39 | O7: 166.36 | P7: 173.33 | Q7: 117.57 | R7: 117.57 | S7: 101.85
A8: ATÉ 2,50 | B8: =SUM(L8-(L8*Capa!$C$1)) -> 168.833 | C8: =SUM(M8-(M8*Capa!$C$1)) -> 177.5455 | D8: =SUM(N8-(N8*Capa!$C$1)) -> 186.258 | E8: =SUM(O8-(O8*Capa!$C$1)) -> 194.9705 | F8: =SUM(P8-(P8*Capa!$C$1)) -> 203.683 | G8: =SUM(Q8-(Q8*Capa!$C$1)) -> 133.983 | H8: =SUM(R8-(R8*Capa!$C$1)) -> 133.983 | I8: =SUM(S8-(S8*Capa!$C$1)) -> 114.46 | K8: ATÉ 2,50 | L8: 168.833 | M8: 177.5455 | N8: 186.258 | O8: 194.9705 | P8: 203.683 | Q8: 133.983 | R8: 133.983 | S8: 114.46
A9: ATÉ 3,00 | B9: =SUM(L9-(L9*Capa!$C$1)) -> 193.974 | C9: =SUM(M9-(M9*Capa!$C$1)) -> 204.429 | D9: =SUM(N9-(N9*Capa!$C$1)) -> 214.884 | E9: =SUM(O9-(O9*Capa!$C$1)) -> 225.339 | F9: =SUM(P9-(P9*Capa!$C$1)) -> 235.794 | G9: =SUM(Q9-(Q9*Capa!$C$1)) -> 152.154 | H9: =SUM(R9-(R9*Capa!$C$1)) -> 152.154 | I9: =SUM(S9-(S9*Capa!$C$1)) -> 129.98 | K9: ATÉ 3,00 | L9: 193.974 | M9: 204.429 | N9: 214.884 | O9: 225.339 | P9: 235.794 | Q9: 152.154 | R9: 152.154 | S9: 129.98
A10: ATÉ 3,50 | B10: =SUM(L10-(L10*Capa!$C$1)) -> 217.357 | C10: =SUM(M10-(M10*Capa!$C$1)) -> 229.5545 | D10: =SUM(N10-(N10*Capa!$C$1)) -> 241.752 | E10: =SUM(O10-(O10*Capa!$C$1)) -> 253.9495 | F10: =SUM(P10-(P10*Capa!$C$1)) -> 266.147 | G10: =SUM(Q10-(Q10*Capa!$C$1)) -> 168.567 | H10: =SUM(R10-(R10*Capa!$C$1)) -> 168.567 | I10: =SUM(S10-(S10*Capa!$C$1)) -> 142.59 | K10: ATÉ 3,50 | L10: 217.357 | M10: 229.5545 | N10: 241.752 | O10: 253.9495 | P10: 266.147 | Q10: 168.567 | R10: 168.567 | S10: 142.59
A11: ATÉ 4,00 | B11: =SUM(L11-(L11*Capa!$C$1)) -> 242.108 | C11: =SUM(M11-(M11*Capa!$C$1)) -> 256.048 | D11: =SUM(N11-(N11*Capa!$C$1)) -> 269.988 | E11: =SUM(O11-(O11*Capa!$C$1)) -> 283.928 | F11: =SUM(P11-(P11*Capa!$C$1)) -> 297.868 | G11: =SUM(Q11-(Q11*Capa!$C$1)) -> 186.348 | H11: =SUM(R11-(R11*Capa!$C$1)) -> 186.348 | I11: =SUM(S11-(S11*Capa!$C$1)) -> 148.89 | K11: ATÉ 4,00 | L11: 242.108 | M11: 256.048 | N11: 269.988 | O11: 283.928 | P11: 297.868 | Q11: 186.348 | R11: 186.348 | S11: 148.89
A12: ATÉ 4,50 | B12: =SUM(L12-(L12*Capa!$C$1)) -> 265.687 | C12: =SUM(M12-(M12*Capa!$C$1)) -> 281.3695 | D12: =SUM(N12-(N12*Capa!$C$1)) -> 297.052 | E12: =SUM(O12-(O12*Capa!$C$1)) -> 312.7345 | F12: =SUM(P12-(P12*Capa!$C$1)) -> 328.417 | G12: =SUM(Q12-(Q12*Capa!$C$1)) -> 202.957 | H12: =SUM(R12-(R12*Capa!$C$1)) -> 202.957 | I12: =SUM(S12-(S12*Capa!$C$1)) -> 155.2 | K12: ATÉ 4,50 | L12: 265.687 | M12: 281.3695 | N12: 297.052 | O12: 312.7345 | P12: 328.417 | Q12: 202.957 | R12: 202.957 | S12: 155.2
A13: ATÉ 5,00 | B13: =SUM(L13-(L13*Capa!$C$1)) -> 294.71 | C13: =SUM(M13-(M13*Capa!$C$1)) -> 312.135 | D13: =SUM(N13-(N13*Capa!$C$1)) -> 329.56 | E13: =SUM(O13-(O13*Capa!$C$1)) -> 346.985 | F13: =SUM(P13-(P13*Capa!$C$1)) -> 364.41 | G13: =SUM(Q13-(Q13*Capa!$C$1)) -> 225.01 | H13: =SUM(R13-(R13*Capa!$C$1)) -> 225.01 | I13: =SUM(S13-(S13*Capa!$C$1)) -> 186.24 | K13: ATÉ 5,00 | L13: 294.71 | M13: 312.135 | N13: 329.56 | O13: 346.985 | P13: 364.41 | Q13: 225.01 | R13: 225.01 | S13: 186.24
A14: ATÉ 5,50 | B14: =SUM(L14-(L14*Capa!$C$1)) -> 315.963 | C14: =SUM(M14-(M14*Capa!$C$1)) -> 335.1305 | D14: =SUM(N14-(N14*Capa!$C$1)) -> 354.298 | E14: =SUM(O14-(O14*Capa!$C$1)) -> 373.4655 | F14: =SUM(P14-(P14*Capa!$C$1)) -> 392.633 | G14: =SUM(Q14-(Q14*Capa!$C$1)) -> 239.293 | H14: =SUM(R14-(R14*Capa!$C$1)) -> 239.293 | I14: =SUM(S14-(S14*Capa!$C$1)) -> 188.18 | K14: ATÉ 5,50 | L14: 315.963 | M14: 335.1305 | N14: 354.298 | O14: 373.4655 | P14: 392.633 | Q14: 239.293 | R14: 239.293 | S14: 188.18
A15: ATÉ 6,00 | B15: =SUM(L15-(L15*Capa!$C$1)) -> 339.36 | C15: =SUM(M15-(M15*Capa!$C$1)) -> 360.27 | D15: =SUM(N15-(N15*Capa!$C$1)) -> 381.18 | E15: =SUM(O15-(O15*Capa!$C$1)) -> 402.09 | F15: =SUM(P15-(P15*Capa!$C$1)) -> 423 | G15: =SUM(Q15-(Q15*Capa!$C$1)) -> 255.72 | H15: =SUM(R15-(R15*Capa!$C$1)) -> 255.72 | I15: =SUM(S15-(S15*Capa!$C$1)) -> 190.12 | K15: ATÉ 6,00 | L15: 339.36 | M15: 360.27 | N15: 381.18 | O15: 402.09 | P15: 423 | Q15: 255.72 | R15: 255.72 | S15: 190.12
A16: VARÃO PRIME MONTADO SEM ACIONAMENTO
A17: CORES: CROMADO, AÇO ESCOVADO, BRANCO, PRETO,DOURADO,OURO VELHO E OURO ROSE
A18: MEDIDA | B18: 2 X 1 | C18: 2,5 X 1 | D18: 3 X 1 | E18: 3,5 X 1 | F18: 4 X 1 | G18: S/ FITA | H18: WAVE PLUS | I18: FRANZIDO | K18: MEDIDA | L18: 2 X 1 | M18: 2,5 X 1 | N18: 3 X 1 | O18: 3,5 X 1 | P18: 4 X 1 | Q18: S/ FITA | R18: WAVE PLUS | S18: FRANZIDO
A19: ATÉ 1,00 | B19: =SUM(L19-(L19*Capa!$C$1)) -> 65.57 | C19: =SUM(M19-(M19*Capa!$C$1)) -> 69.055 | D19: =SUM(N19-(N19*Capa!$C$1)) -> 72.54 | E19: =SUM(O19-(O19*Capa!$C$1)) -> 76.025 | F19: =SUM(P19-(P19*Capa!$C$1)) -> 79.51 | G19: =SUM(Q19-(Q19*Capa!$C$1)) -> 51.63 | H19: =SUM(R19-(R19*Capa!$C$1)) -> 51.63 | I19: =SUM(S19-(S19*Capa!$C$1)) -> 41.71 | K19: ATÉ 1,00 | L19: 65.57 | M19: 69.055 | N19: 72.54 | O19: 76.025 | P19: 79.51 | Q19: 51.63 | R19: 51.63 | S19: 41.71
A20: ATÉ 1,50 | B20: =SUM(L20-(L20*Capa!$C$1)) -> 87.977 | C20: =SUM(M20-(M20*Capa!$C$1)) -> 93.2045 | D20: =SUM(N20-(N20*Capa!$C$1)) -> 98.432 | E20: =SUM(O20-(O20*Capa!$C$1)) -> 103.6595 | F20: =SUM(P20-(P20*Capa!$C$1)) -> 108.887 | G20: =SUM(Q20-(Q20*Capa!$C$1)) -> 67.067 | H20: =SUM(R20-(R20*Capa!$C$1)) -> 67.067 | I20: =SUM(S20-(S20*Capa!$C$1)) -> 54.32 | K20: ATÉ 1,50 | L20: 87.977 | M20: 93.2045 | N20: 98.432 | O20: 103.6595 | P20: 108.887 | Q20: 67.067 | R20: 67.067 | S20: 54.32
A21: ATÉ 2,00 | B21: =SUM(L21-(L21*Capa!$C$1)) -> 112.936 | C21: =SUM(M21-(M21*Capa!$C$1)) -> 119.906 | D21: =SUM(N21-(N21*Capa!$C$1)) -> 126.876 | E21: =SUM(O21-(O21*Capa!$C$1)) -> 133.846 | F21: =SUM(P21-(P21*Capa!$C$1)) -> 140.816 | G21: =SUM(Q21-(Q21*Capa!$C$1)) -> 85.056 | H21: =SUM(R21-(R21*Capa!$C$1)) -> 85.056 | I21: =SUM(S21-(S21*Capa!$C$1)) -> 68.87 | K21: ATÉ 2,00 | L21: 112.936 | M21: 119.906 | N21: 126.876 | O21: 133.846 | P21: 140.816 | Q21: 85.056 | R21: 85.056 | S21: 68.87
A22: ATÉ 2,50 | B22: =SUM(L22-(L22*Capa!$C$1)) -> 135.135 | C22: =SUM(M22-(M22*Capa!$C$1)) -> 143.8475 | D22: =SUM(N22-(N22*Capa!$C$1)) -> 152.56 | E22: =SUM(O22-(O22*Capa!$C$1)) -> 161.2725 | F22: =SUM(P22-(P22*Capa!$C$1)) -> 169.985 | G22: =SUM(Q22-(Q22*Capa!$C$1)) -> 100.285 | H22: =SUM(R22-(R22*Capa!$C$1)) -> 100.285 | I22: =SUM(S22-(S22*Capa!$C$1)) -> 80.51 | K22: ATÉ 2,50 | L22: 135.135 | M22: 143.8475 | N22: 152.56 | O22: 161.2725 | P22: 169.985 | Q22: 100.285 | R22: 100.285 | S22: 80.51
A23: ATÉ 3,00 | B23: =SUM(L23-(L23*Capa!$C$1)) -> 159.504 | C23: =SUM(M23-(M23*Capa!$C$1)) -> 169.959 | D23: =SUM(N23-(N23*Capa!$C$1)) -> 180.414 | E23: =SUM(O23-(O23*Capa!$C$1)) -> 190.869 | F23: =SUM(P23-(P23*Capa!$C$1)) -> 201.324 | G23: =SUM(Q23-(Q23*Capa!$C$1)) -> 117.684 | H23: =SUM(R23-(R23*Capa!$C$1)) -> 117.684 | I23: =SUM(S23-(S23*Capa!$C$1)) -> 95.06 | K23: ATÉ 3,00 | L23: 159.504 | M23: 169.959 | N23: 180.414 | O23: 190.869 | P23: 201.324 | Q23: 117.684 | R23: 117.684 | S23: 95.06
A24: ATÉ 3,50 | B24: =SUM(L24-(L24*Capa!$C$1)) -> 182.087 | C24: =SUM(M24-(M24*Capa!$C$1)) -> 194.2845 | D24: =SUM(N24-(N24*Capa!$C$1)) -> 206.482 | E24: =SUM(O24-(O24*Capa!$C$1)) -> 218.6795 | F24: =SUM(P24-(P24*Capa!$C$1)) -> 230.877 | G24: =SUM(Q24-(Q24*Capa!$C$1)) -> 133.297 | H24: =SUM(R24-(R24*Capa!$C$1)) -> 133.297 | I24: =SUM(S24-(S24*Capa!$C$1)) -> 107.67 | K24: ATÉ 3,50 | L24: 182.087 | M24: 194.2845 | N24: 206.482 | O24: 218.6795 | P24: 230.877 | Q24: 133.297 | R24: 133.297 | S24: 107.67
A25: ATÉ 4,00 | B25: =SUM(L25-(L25*Capa!$C$1)) -> 207.034 | C25: =SUM(M25-(M25*Capa!$C$1)) -> 220.974 | D25: =SUM(N25-(N25*Capa!$C$1)) -> 234.914 | E25: =SUM(O25-(O25*Capa!$C$1)) -> 248.854 | F25: =SUM(P25-(P25*Capa!$C$1)) -> 262.794 | G25: =SUM(Q25-(Q25*Capa!$C$1)) -> 151.274 | H25: =SUM(R25-(R25*Capa!$C$1)) -> 151.274 | I25: =SUM(S25-(S25*Capa!$C$1)) -> 122.22 | K25: ATÉ 4,00 | L25: 207.034 | M25: 220.974 | N25: 234.914 | O25: 248.854 | P25: 262.794 | Q25: 151.274 | R25: 151.274 | S25: 122.22
A26: ATÉ 4,50 | B26: =SUM(L26-(L26*Capa!$C$1)) -> 229.095 | C26: =SUM(M26-(M26*Capa!$C$1)) -> 244.7775 | D26: =SUM(N26-(N26*Capa!$C$1)) -> 260.46 | E26: =SUM(O26-(O26*Capa!$C$1)) -> 276.1425 | F26: =SUM(P26-(P26*Capa!$C$1)) -> 291.825 | G26: =SUM(Q26-(Q26*Capa!$C$1)) -> 166.365 | H26: =SUM(R26-(R26*Capa!$C$1)) -> 166.365 | I26: =SUM(S26-(S26*Capa!$C$1)) -> 133.86 | K26: ATÉ 4,50 | L26: 229.095 | M26: 244.7775 | N26: 260.46 | O26: 276.1425 | P26: 291.825 | Q26: 166.365 | R26: 166.365 | S26: 133.86
A27: ATÉ 5,00 | B27: =SUM(L27-(L27*Capa!$C$1)) -> 258.458 | C27: =SUM(M27-(M27*Capa!$C$1)) -> 275.883 | D27: =SUM(N27-(N27*Capa!$C$1)) -> 293.308 | E27: =SUM(O27-(O27*Capa!$C$1)) -> 310.733 | F27: =SUM(P27-(P27*Capa!$C$1)) -> 328.158 | G27: =SUM(Q27-(Q27*Capa!$C$1)) -> 188.758 | H27: =SUM(R27-(R27*Capa!$C$1)) -> 188.758 | I27: =SUM(S27-(S27*Capa!$C$1)) -> 149.38 | K27: ATÉ 5,00 | L27: 258.458 | M27: 275.883 | N27: 293.308 | O27: 310.733 | P27: 328.158 | Q27: 188.758 | R27: 188.758 | S27: 149.38
A28: ATÉ 5,50 | B28: =SUM(L28-(L28*Capa!$C$1)) -> 279.701 | C28: =SUM(M28-(M28*Capa!$C$1)) -> 298.8685 | D28: =SUM(N28-(N28*Capa!$C$1)) -> 318.036 | E28: =SUM(O28-(O28*Capa!$C$1)) -> 337.2035 | F28: =SUM(P28-(P28*Capa!$C$1)) -> 356.371 | G28: =SUM(Q28-(Q28*Capa!$C$1)) -> 203.031 | H28: =SUM(R28-(R28*Capa!$C$1)) -> 203.031 | I28: =SUM(S28-(S28*Capa!$C$1)) -> 162.47 | K28: ATÉ 5,50 | L28: 279.701 | M28: 298.8685 | N28: 318.036 | O28: 337.2035 | P28: 356.371 | Q28: 203.031 | R28: 203.031 | S28: 162.47
A29: ATÉ 6,00 | B29: =SUM(L29-(L29*Capa!$C$1)) -> 300.948 | C29: =SUM(M29-(M29*Capa!$C$1)) -> 321.858 | D29: =SUM(N29-(N29*Capa!$C$1)) -> 342.768 | E29: =SUM(O29-(O29*Capa!$C$1)) -> 363.678 | F29: =SUM(P29-(P29*Capa!$C$1)) -> 384.588 | G29: =SUM(Q29-(Q29*Capa!$C$1)) -> 217.308 | H29: =SUM(R29-(R29*Capa!$C$1)) -> 217.308 | I29: =SUM(S29-(S29*Capa!$C$1)) -> 175.57 | K29: ATÉ 6,00 | L29: 300.948 | M29: 321.858 | N29: 342.768 | O29: 363.678 | P29: 384.588 | Q29: 217.308 | R29: 217.308 | S29: 175.57
A30: SUPORTES
A31: STYT | B31: SUPORTE SIMPLES BARI C/ TRAVA *LANÇAMENTO | I31: ='Wave-Square-Retangular'!G18 -> 9.66
A32: STY | B32: SUPORTE SIMPLES BARI | I32: ='Wave-Square-Retangular'!G19 -> 9.66
A33: STDYT | B33: SUPORTE DUPLO BARI C/ TRAVA *LANÇAMENTO | I33: ='Wave-Square-Retangular'!G20 -> 14.7
A34: STDY | B34: SUPORTE DUPLO BARI | I34: ='Wave-Square-Retangular'!G21 -> 14.7
A35: CLTST | B35: SUPORTE CHAPA SIMPLES P/ TETO C/ TRAVA BRANCO / PRETO *LANÇAMENTO | I35: ='Wave-Square-Retangular'!G22 -> 4.74
A36: CLTS | B36: SUPORTE CHAPA SIMPLES P/ TETO BRANCO / PRETO | I36: ='Wave-Square-Retangular'!G23 -> 4.74
A37: CLTDAT | B37: SUPORTE CHAPA DUPLO P/ TETO C/ TRAVA BRANCO / PRETO *LANÇAMENTO | I37: ='Wave-Square-Retangular'!G24 -> 7.59
A38: CLTDA | B38: SUPORTE CHAPA DUPLO P/ TETO BRANCO / PRETO | I38: ='Wave-Square-Retangular'!G25 -> 7.59
A39: SLR | B39: SUPORTE L COM REGULAGEM DUPLO 7 X 12 | I39: ='Wave-Square-Retangular'!G29 -> 11.5
A40: SSW | B40: SUPORTE L SIMPLES 7 X 7 P/ WAVE | I40: ='Wave-Square-Retangular'!G30 -> 9.66
A41: SLMA | B41: SUPORTE SIMPLES MASTER | I41: ='Wave-Square-Retangular'!G31 -> 29.36
...

Sheet Trilho Slim Montado
A2: TRILHO SLIM MONTADO COM ACIONAMENTO NO MODELO COM ABA OU COM PRESILHA
A3: COR: BRANCO E PRETO
A4: MEDIDA | B4: 2 X 1 | C4: 2,5 X 1 | D4: 3 X 1 | E4: 3,5 X 1 | F4: 4 X 1 | G4: S/ FITA | H4: WAVE PLUS | I4: FRANZIDO | K4: MEDIDA | L4: 2 X 1 | M4: 2,5 X 1 | N4: 3 X 1 | O4: 3,5 X 1 | P4: 4 X 1 | Q4: S/ FITA | R4: WAVE PLUS | S4: FRANZIDO
A5: ATÉ 1,00 | B5: =SUM(L5-(L5*Capa!$C$1)) -> 71.746 | C5: =SUM(M5-(M5*Capa!$C$1)) -> 75.231 | D5: =SUM(N5-(N5*Capa!$C$1)) -> 78.716 | E5: =SUM(O5-(O5*Capa!$C$1)) -> 82.201 | F5: =SUM(P5-(P5*Capa!$C$1)) -> 85.686 | G5: =SUM(Q5-(Q5*Capa!$C$1)) -> 57.806 | H5: =SUM(R5-(R5*Capa!$C$1)) -> 57.806 | I5: =SUM(S5-(S5*Capa!$C$1)) -> 50.35 | K5: ATÉ 1,00 | L5: 71.746 | M5: 75.231 | N5: 78.716 | O5: 82.201 | P5: 85.686 | Q5: 57.806 | R5: 57.806 | S5: 50.35
A6: ATÉ 1,50 | B6: =SUM(L6-(L6*Capa!$C$1)) -> 86.141 | C6: =SUM(M6-(M6*Capa!$C$1)) -> 91.3685 | D6: =SUM(N6-(N6*Capa!$C$1)) -> 96.596 | E6: =SUM(O6-(O6*Capa!$C$1)) -> 101.8235 | F6: =SUM(P6-(P6*Capa!$C$1)) -> 107.051 | G6: =SUM(Q6-(Q6*Capa!$C$1)) -> 65.231 | H6: =SUM(R6-(R6*Capa!$C$1)) -> 65.231 | I6: =SUM(S6-(S6*Capa!$C$1)) -> 57 | K6: ATÉ 1,50 | L6: 86.141 | M6: 91.3685 | N6: 96.596 | O6: 101.8235 | P6: 107.051 | Q6: 65.231 | R6: 65.231 | S6: 57
A7: ATÉ 2,00 | B7: =SUM(L7-(L7*Capa!$C$1)) -> 104.144 | C7: =SUM(M7-(M7*Capa!$C$1)) -> 111.114 | D7: =SUM(N7-(N7*Capa!$C$1)) -> 118.084 | E7: =SUM(O7-(O7*Capa!$C$1)) -> 125.054 | F7: =SUM(P7-(P7*Capa!$C$1)) -> 132.024 | G7: =SUM(Q7-(Q7*Capa!$C$1)) -> 76.264 | H7: =SUM(R7-(R7*Capa!$C$1)) -> 76.264 | I7: =SUM(S7-(S7*Capa!$C$1)) -> 63.65 | K7: ATÉ 2,00 | L7: 104.144 | M7: 111.114 | N7: 118.084 | O7: 125.054 | P7: 132.024 | Q7: 76.264 | R7: 76.264 | S7: 63.65
A8: ATÉ 2,50 | B8: =SUM(L8-(L8*Capa!$C$1)) -> 120.249 | C8: =SUM(M8-(M8*Capa!$C$1)) -> 128.9615 | D8: =SUM(N8-(N8*Capa!$C$1)) -> 137.674 | E8: =SUM(O8-(O8*Capa!$C$1)) -> 146.3865 | F8: =SUM(P8-(P8*Capa!$C$1)) -> 155.099 | G8: =SUM(Q8-(Q8*Capa!$C$1)) -> 85.399 | H8: =SUM(R8-(R8*Capa!$C$1)) -> 85.399 | I8: =SUM(S8-(S8*Capa!$C$1)) -> 70.3 | K8: ATÉ 2,50 | L8: 120.249 | M8: 128.9615 | N8: 137.674 | O8: 146.3865 | P8: 155.099 | Q8: 85.399 | R8: 85.399 | S8: 70.3
A9: ATÉ 3,00 | B9: =SUM(L9-(L9*Capa!$C$1)) -> 138.052 | C9: =SUM(M9-(M9*Capa!$C$1)) -> 148.507 | D9: =SUM(N9-(N9*Capa!$C$1)) -> 158.962 | E9: =SUM(O9-(O9*Capa!$C$1)) -> 169.417 | F9: =SUM(P9-(P9*Capa!$C$1)) -> 179.872 | G9: =SUM(Q9-(Q9*Capa!$C$1)) -> 96.232 | H9: =SUM(R9-(R9*Capa!$C$1)) -> 96.232 | I9: =SUM(S9-(S9*Capa!$C$1)) -> 76.95 | K9: ATÉ 3,00 | L9: 138.052 | M9: 148.507 | N9: 158.962 | O9: 169.417 | P9: 179.872 | Q9: 96.232 | R9: 96.232 | S9: 76.95
A10: ATÉ 3,50 | B10: =SUM(L10-(L10*Capa!$C$1)) -> 154.157 | C10: =SUM(M10-(M10*Capa!$C$1)) -> 166.3545 | D10: =SUM(N10-(N10*Capa!$C$1)) -> 178.552 | E10: =SUM(O10-(O10*Capa!$C$1)) -> 190.7495 | F10: =SUM(P10-(P10*Capa!$C$1)) -> 202.947 | G10: =SUM(Q10-(Q10*Capa!$C$1)) -> 105.367 | H10: =SUM(R10-(R10*Capa!$C$1)) -> 105.367 | I10: =SUM(S10-(S10*Capa!$C$1)) -> 83.6 | K10: ATÉ 3,50 | L10: 154.157 | M10: 166.3545 | N10: 178.552 | O10: 190.7495 | P10: 202.947 | Q10: 105.367 | R10: 105.367 | S10: 83.6
A11: ATÉ 4,00 | B11: =SUM(L11-(L11*Capa!$C$1)) -> 170.07 | C11: =SUM(M11-(M11*Capa!$C$1)) -> 184.01 | D11: =SUM(N11-(N11*Capa!$C$1)) -> 197.95 | E11: =SUM(O11-(O11*Capa!$C$1)) -> 211.89 | F11: =SUM(P11-(P11*Capa!$C$1)) -> 225.83 | G11: =SUM(Q11-(Q11*Capa!$C$1)) -> 114.31 | H11: =SUM(R11-(R11*Capa!$C$1)) -> 114.31 | I11: =SUM(S11-(S11*Capa!$C$1)) -> 90.25 | K11: ATÉ 4,00 | L11: 170.07 | M11: 184.01 | N11: 197.95 | O11: 211.89 | P11: 225.83 | Q11: 114.31 | R11: 114.31 | S11: 90.25
A12: ATÉ 4,50 | B12: =SUM(L12-(L12*Capa!$C$1)) -> 185.595 | C12: =SUM(M12-(M12*Capa!$C$1)) -> 201.2775 | D12: =SUM(N12-(N12*Capa!$C$1)) -> 216.96 | E12: =SUM(O12-(O12*Capa!$C$1)) -> 232.6425 | F12: =SUM(P12-(P12*Capa!$C$1)) -> 248.325 | G12: =SUM(Q12-(Q12*Capa!$C$1)) -> 122.865 | H12: =SUM(R12-(R12*Capa!$C$1)) -> 122.865 | I12: =SUM(S12-(S12*Capa!$C$1)) -> 96.9 | K12: ATÉ 4,50 | L12: 185.595 | M12: 201.2775 | N12: 216.96 | O12: 232.6425 | P12: 248.325 | Q12: 122.865 | R12: 122.865 | S12: 96.9
A13: ATÉ 5,00 | B13: =SUM(L13-(L13*Capa!$C$1)) -> 209.756 | C13: =SUM(M13-(M13*Capa!$C$1)) -> 227.181 | D13: =SUM(N13-(N13*Capa!$C$1)) -> 244.606 | E13: =SUM(O13-(O13*Capa!$C$1)) -> 262.031 | F13: =SUM(P13-(P13*Capa!$C$1)) -> 279.456 | G13: =SUM(Q13-(Q13*Capa!$C$1)) -> 140.056 | H13: =SUM(R13-(R13*Capa!$C$1)) -> 140.056 | I13: =SUM(S13-(S13*Capa!$C$1)) -> 112.1 | K13: ATÉ 5,00 | L13: 209.756 | M13: 227.181 | N13: 244.606 | O13: 262.031 | P13: 279.456 | Q13: 140.056 | R13: 140.056 | S13: 112.1
A14: ATÉ 5,50 | B14: =SUM(L14-(L14*Capa!$C$1)) -> 221.349 | C14: =SUM(M14-(M14*Capa!$C$1)) -> 240.5165 | D14: =SUM(N14-(N14*Capa!$C$1)) -> 259.684 | E14: =SUM(O14-(O14*Capa!$C$1)) -> 278.8515 | F14: =SUM(P14-(P14*Capa!$C$1)) -> 298.019 | G14: =SUM(Q14-(Q14*Capa!$C$1)) -> 144.679 | H14: =SUM(R14-(R14*Capa!$C$1)) -> 144.679 | I14: =SUM(S14-(S14*Capa!$C$1)) -> 114.47 | K14: ATÉ 5,50 | L14: 221.349 | M14: 240.5165 | N14: 259.684 | O14: 278.8515 | P14: 298.019 | Q14: 144.679 | R14: 144.679 | S14: 114.47
A15: ATÉ 6,00 | B15: =SUM(L15-(L15*Capa!$C$1)) -> 232.948 | C15: =SUM(M15-(M15*Capa!$C$1)) -> 253.858 | D15: =SUM(N15-(N15*Capa!$C$1)) -> 274.768 | E15: =SUM(O15-(O15*Capa!$C$1)) -> 295.678 | F15: =SUM(P15-(P15*Capa!$C$1)) -> 316.588 | G15: =SUM(Q15-(Q15*Capa!$C$1)) -> 149.308 | H15: =SUM(R15-(R15*Capa!$C$1)) -> 149.308 | I15: =SUM(S15-(S15*Capa!$C$1)) -> 116.85 | K15: ATÉ 6,00 | L15: 232.948 | M15: 253.858 | N15: 274.768 | O15: 295.678 | P15: 316.588 | Q15: 149.308 | R15: 149.308 | S15: 116.85
A16: TRILHO SLIM MONTADO SEM ACIONAMENTO NO MODELO COM ABA OU COM PRESILHA
A17: COR: BRANCO E PRETO
A18: MEDIDA | B18: 2 X 1 | C18: 2,5 X 1 | D18: 3 X 1 | E18: 3,5 X 1 | F18: 4 X 1 | G18: S/ FITA | H18: WAVE PLUS | I18: FRANZIDO | K18: MEDIDA | L18: 2 X 1 | M18: 2,5 X 1 | N18: 3 X 1 | O18: 3,5 X 1 | P18: 4 X 1 | Q18: S/ FITA | R18: WAVE PLUS | S18: FRANZIDO
A19: ATÉ 1,00 | B19: =SUM(L19-(L19*Capa!$C$1)) -> 55.838 | C19: =SUM(M19-(M19*Capa!$C$1)) -> 59.323 | D19: =SUM(N19-(N19*Capa!$C$1)) -> 62.808 | E19: =SUM(O19-(O19*Capa!$C$1)) -> 66.293 | F19: =SUM(P19-(P19*Capa!$C$1)) -> 69.778 | G19: =SUM(Q19-(Q19*Capa!$C$1)) -> 41.898 | H19: =SUM(R19-(R19*Capa!$C$1)) -> 41.898 | I19: =SUM(S19-(S19*Capa!$C$1)) -> 36.1 | K19: ATÉ 1,00 | L19: 55.838 | M19: 59.323 | N19: 62.808 | O19: 66.293 | P19: 69.778 | Q19: 41.898 | R19: 41.898 | S19: 36.1
A20: ATÉ 1,50 | B20: =SUM(L20-(L20*Capa!$C$1)) -> 65.763 | C20: =SUM(M20-(M20*Capa!$C$1)) -> 70.9905 | D20: =SUM(N20-(N20*Capa!$C$1)) -> 76.218 | E20: =SUM(O20-(O20*Capa!$C$1)) -> 81.4455 | F20: =SUM(P20-(P20*Capa!$C$1)) -> 86.673 | G20: =SUM(Q20-(Q20*Capa!$C$1)) -> 44.853 | H20: =SUM(R20-(R20*Capa!$C$1)) -> 44.853 | I20: =SUM(S20-(S20*Capa!$C$1)) -> 39.9 | K20: ATÉ 1,50 | L20: 65.763 | M20: 70.9905 | N20: 76.218 | O20: 81.4455 | P20: 86.673 | Q20: 44.853 | R20: 44.853 | S20: 39.9
A21: ATÉ 2,00 | B21: =SUM(L21-(L21*Capa!$C$1)) -> 81.686 | C21: =SUM(M21-(M21*Capa!$C$1)) -> 88.656 | D21: =SUM(N21-(N21*Capa!$C$1)) -> 95.626 | E21: =SUM(O21-(O21*Capa!$C$1)) -> 102.596 | F21: =SUM(P21-(P21*Capa!$C$1)) -> 109.566 | G21: =SUM(Q21-(Q21*Capa!$C$1)) -> 53.806 | H21: =SUM(R21-(R21*Capa!$C$1)) -> 53.806 | I21: =SUM(S21-(S21*Capa!$C$1)) -> 47.5 | K21: ATÉ 2,00 | L21: 81.686 | M21: 88.656 | N21: 95.626 | O21: 102.596 | P21: 109.566 | Q21: 53.806 | R21: 53.806 | S21: 47.5
A22: ATÉ 2,50 | B22: =SUM(L22-(L22*Capa!$C$1)) -> 97.039 | C22: =SUM(M22-(M22*Capa!$C$1)) -> 105.7515 | D22: =SUM(N22-(N22*Capa!$C$1)) -> 114.464 | E22: =SUM(O22-(O22*Capa!$C$1)) -> 123.1765 | F22: =SUM(P22-(P22*Capa!$C$1)) -> 131.889 | G22: =SUM(Q22-(Q22*Capa!$C$1)) -> 62.189 | H22: =SUM(R22-(R22*Capa!$C$1)) -> 62.189 | I22: =SUM(S22-(S22*Capa!$C$1)) -> 52.25 | K22: ATÉ 2,50 | L22: 97.039 | M22: 105.7515 | N22: 114.464 | O22: 123.1765 | P22: 131.889 | Q22: 62.189 | R22: 62.189 | S22: 52.25
A23: ATÉ 3,00 | B23: =SUM(L23-(L23*Capa!$C$1)) -> 113.144 | C23: =SUM(M23-(M23*Capa!$C$1)) -> 123.599 | D23: =SUM(N23-(N23*Capa!$C$1)) -> 134.054 | E23: =SUM(O23-(O23*Capa!$C$1)) -> 144.509 | F23: =SUM(P23-(P23*Capa!$C$1)) -> 154.964 | G23: =SUM(Q23-(Q23*Capa!$C$1)) -> 71.324 | H23: =SUM(R23-(R23*Capa!$C$1)) -> 71.324 | I23: =SUM(S23-(S23*Capa!$C$1)) -> 57.95 | K23: ATÉ 3,00 | L23: 113.144 | M23: 123.599 | N23: 134.054 | O23: 144.509 | P23: 154.964 | Q23: 71.324 | R23: 71.324 | S23: 57.95
A24: ATÉ 3,50 | B24: =SUM(L24-(L24*Capa!$C$1)) -> 125.011 | C24: =SUM(M24-(M24*Capa!$C$1)) -> 137.2085 | D24: =SUM(N24-(N24*Capa!$C$1)) -> 149.406 | E24: =SUM(O24-(O24*Capa!$C$1)) -> 161.6035 | F24: =SUM(P24-(P24*Capa!$C$1)) -> 173.801 | G24: =SUM(Q24-(Q24*Capa!$C$1)) -> 76.221 | H24: =SUM(R24-(R24*Capa!$C$1)) -> 76.221 | I24: =SUM(S24-(S24*Capa!$C$1)) -> 60.8 | K24: ATÉ 3,50 | L24: 125.011 | M24: 137.2085 | N24: 149.406 | O24: 161.6035 | P24: 173.801 | Q24: 76.221 | R24: 76.221 | S24: 60.8
A25: ATÉ 4,00 | B25: =SUM(L25-(L25*Capa!$C$1)) -> 140.924 | C25: =SUM(M25-(M25*Capa!$C$1)) -> 154.864 | D25: =SUM(N25-(N25*Capa!$C$1)) -> 168.804 | E25: =SUM(O25-(O25*Capa!$C$1)) -> 182.744 | F25: =SUM(P25-(P25*Capa!$C$1)) -> 196.684 | G25: =SUM(Q25-(Q25*Capa!$C$1)) -> 85.164 | H25: =SUM(R25-(R25*Capa!$C$1)) -> 85.164 | I25: =SUM(S25-(S25*Capa!$C$1)) -> 70.3 | K25: ATÉ 4,00 | L25: 140.924 | M25: 154.864 | N25: 168.804 | O25: 182.744 | P25: 196.684 | Q25: 85.164 | R25: 85.164 | S25: 70.3
A26: ATÉ 4,50 | B26: =SUM(L26-(L26*Capa!$C$1)) -> 154.459 | C26: =SUM(M26-(M26*Capa!$C$1)) -> 170.1415 | D26: =SUM(N26-(N26*Capa!$C$1)) -> 185.824 | E26: =SUM(O26-(O26*Capa!$C$1)) -> 201.5065 | F26: =SUM(P26-(P26*Capa!$C$1)) -> 217.189 | G26: =SUM(Q26-(Q26*Capa!$C$1)) -> 91.729 | H26: =SUM(R26-(R26*Capa!$C$1)) -> 91.729 | I26: =SUM(S26-(S26*Capa!$C$1)) -> 75.05 | K26: ATÉ 4,50 | L26: 154.459 | M26: 170.1415 | N26: 185.824 | O26: 201.5065 | P26: 217.189 | Q26: 91.729 | R26: 91.729 | S26: 75.05
A27: ATÉ 5,00 | B27: =SUM(L27-(L27*Capa!$C$1)) -> 173.684 | C27: =SUM(M27-(M27*Capa!$C$1)) -> 191.109 | D27: =SUM(N27-(N27*Capa!$C$1)) -> 208.534 | E27: =SUM(O27-(O27*Capa!$C$1)) -> 225.959 | F27: =SUM(P27-(P27*Capa!$C$1)) -> 243.384 | G27: =SUM(Q27-(Q27*Capa!$C$1)) -> 103.984 | H27: =SUM(R27-(R27*Capa!$C$1)) -> 103.984 | I27: =SUM(S27-(S27*Capa!$C$1)) -> 91.2 | K27: ATÉ 5,00 | L27: 173.684 | M27: 191.109 | N27: 208.534 | O27: 225.959 | P27: 243.384 | Q27: 103.984 | R27: 103.984 | S27: 91.2
A28: ATÉ 5,50 | B28: =SUM(L28-(L28*Capa!$C$1)) -> 186.603 | C28: =SUM(M28-(M28*Capa!$C$1)) -> 205.7705 | D28: =SUM(N28-(N28*Capa!$C$1)) -> 224.938 | E28: =SUM(O28-(O28*Capa!$C$1)) -> 244.1055 | F28: =SUM(P28-(P28*Capa!$C$1)) -> 263.273 | G28: =SUM(Q28-(Q28*Capa!$C$1)) -> 109.933 | H28: =SUM(R28-(R28*Capa!$C$1)) -> 109.933 | I28: =SUM(S28-(S28*Capa!$C$1)) -> 93.57 | K28: ATÉ 5,50 | L28: 186.603 | M28: 205.7705 | N28: 224.938 | O28: 244.1055 | P28: 263.273 | Q28: 109.933 | R28: 109.933 | S28: 93.57
A29: ATÉ 6,00 | B29: =SUM(L29-(L29*Capa!$C$1)) -> 195.528 | C29: =SUM(M29-(M29*Capa!$C$1)) -> 216.438 | D29: =SUM(N29-(N29*Capa!$C$1)) -> 237.348 | E29: =SUM(O29-(O29*Capa!$C$1)) -> 258.258 | F29: =SUM(P29-(P29*Capa!$C$1)) -> 279.168 | G29: =SUM(Q29-(Q29*Capa!$C$1)) -> 111.888 | H29: =SUM(R29-(R29*Capa!$C$1)) -> 111.888 | I29: =SUM(S29-(S29*Capa!$C$1)) -> 95.95 | K29: ATÉ 6,00 | L29: 195.528 | M29: 216.438 | N29: 237.348 | O29: 258.258 | P29: 279.168 | Q29: 111.888 | R29: 111.888 | S29: 95.95
A30: SUPORTES
A31: SLR | B31: SUPORTE L COM REGULAGEM DUPLO 7 X 12 | I31: ='Wave-Square-Retangular'!G29 -> 11.5
A32: SSW | B32: SUPORTE L SIMPLES 7 X 7 P/ WAVE | I32: ='Wave-Square-Retangular'!G30 -> 9.66
A33: AC012P | B33: SUPORTE (L) 05X08 PINTADO | I33: ='Aviamentos-Pingentes'!E27 -> 2.56
A34: AC005P | B34: SUPORTE (L) 03X03 PINTADO | I34: ='Aviamentos-Pingentes'!E28 -> 1.99
A35: AC006P | B35: SUPORTE (L) 05X05 PINTADO | I35: ='Aviamentos-Pingentes'!E29 -> 2.45
A36: AC022P | B36: PRESILHA EM POLIACETAL P/ TRILHO EXTRA - BRANCO E PRETO | I36: =Trilhos!E16 -> 1.32
A37: MODELO WAVE PLUS NÃO ACOMPANHA A ENTRETELA QUE DEVE SER ADQUIRIDA SEPARADAMENTE
A38: PRAZO DE ENTREGA: 7 DIAS PARA TRILHOS NOVOS E 5 DIAS PARA CONSERTO
A39: FAVOR INFORMAR A ALTURA DO COMANDO DAS CORDAS E O MODELO DE ABERTURA

Sheet Trilho Square Montado
A2: TRILHO SQUARE MONTADO COM ACIONAMENTO
A3: CORES: BRANCO, PRETO E CROMADO
A4: MEDIDA | B4: 2 X 1 | C4: 2,5 X 1 | D4: 3 X 1 | E4: 3,5 X 1 | F4: 4 X 1 | G4: S/ FITA | H4: WAVE PLUS | I4: FRANZIDO | K4: MEDIDA | L4: 2 X 1 | M4: 2,5 X 1 | N4: 3 X 1 | O4: 3,5 X 1 | P4: 4 X 1 | Q4: S/ FITA | R4: WAVE PLUS | S4: FRANZIDO
